Workbook
Name RevDemotoConv: #REF!
Name appraisalmultiplecs: #REF!
Name m1bdmproducitivity_preJun: #REF!
Name _C1_Accounts_per_CS: #REF!
Name ClusteroneROW: #REF!
Name Closedwontable: #REF!
Name m4bdmproducitivity_postJun: #REF!
Name NorthAmeria_UK: #REF!
Name NA_C2_ACV: #REF!
Name cbdrmm: #REF!
Name India_SEAME: #REF!
Name North_America___UK: #REF!
Name _C3_System_Implementation: #REF!
Name Auditor_India: #REF!
Name India_C2_ACV: #REF!
Name TE_India: #REF!
Name Changed: #REF!
Name Product___Engg__R_D: #REF!
Name expectedexpansion: #REF!
Name TEmultipleAE: #REF!
Name TEUS: #REF!
Name aeseration: #REF!
Name TEmultipleleader: #REF!
Name Moved1: #REF!
Name TE_US: #REF!
Name productivity2: #REF!
Name USmarekt: #REF!
Name expectedexpansion: #REF!
Name TE_multiple_leader: #REF!
Name cscapacitymax: #REF!
Name iscapacity: #REF!
Name jjellyfishcommissions: #REF!
Name USmarekt: #REF!
Name m1bdmproducitivity_postJun: #REF!
Name NA_C3_SQLtoDemoCVR: #REF!
Name bdmbdrratio: #REF!
Name generalandadmin: #REF!
Name CSTEAmratio: #REF!
Name m3bd: #REF!
Name Auditor_USA: #REF!
Name Product_and_Engineering: #REF!
Name m4bd: #REF!
Name salesandmarketing: #REF!
Name m1bd: #REF!
Name USAEquotaperc: #REF!
Name AE_Seration: #REF!
Name IndiaCScapacity: #REF!
Name IS_ARR: #REF!
Name naentbdr: #REF!
Name Appraisal_Multiple: #REF!
Name sqlconversionperc: #REF!
Name US_AE_Prod: #REF!
Name usaequota: #REF!
Name P_and_E_R_D: #REF!
Name traveltoUS: #REF!
Name NA_C3_ACV: #REF!
Name m4bdmproducitivity_preJun: #REF!
Name India_SEA_ME: #REF!
Name productivity0: #REF!
Name _C1_IS: #REF!

Sheet 1. Business Metrics
E1: Actuals | F1: Actuals | G1: Actuals | H1: Actuals | I1: Actuals | J1: Actuals | K1: Actuals | L1: Actuals | M1: Actuals | N1: Actuals | O1: Actuals | P1: Actuals | Q1: Actuals | R1: Actuals | S1: Actuals | T1: Actuals | U1: Actuals | V1: Planned | W1: Actuals | X1: Planned | Y1: Actuals | Z1: Planned | AA1: Actuals | AB1: Planned | AC1: Actuals | AD1: Planned | AE1: Actuals | AF1: Planned | AG1: Actuals | AH1: Planned | AI1: Actuals | AJ1: Planned | AK1: Actuals | AL1: Planned | AM1: Actuals | AN1: Planned | AO1: Actuals | AP1: Planned | AQ1: Actuals | AR1: Planned | AS1: Actuals | AT1: Planned | AU1: Actuals | AV1: Planned | AW1: Actuals | AX1: Planned | AY1: Actuals | AZ1: Planned | BA1: Actuals | BB1: Planned | BC1: Actuals | BD1: Planned | BE1: Actuals | BF1: Planned | BG1: Actuals | BH1: Planned | BI1: Actuals | BJ1: Planned | BK1: Actuals | BL1: Planned | BM1: Actuals | BN1: Planned | BO1: Actuals | BP1: Planned | BQ1: Actuals | BR1: Planned | BS1: Actuals | BT1: Planned | BU1: Actuals | BV1: Planned | BW1: Actuals | BX1: Planned | BY1: Actuals | BZ1: Planned | CA1: Actuals | CB1: Planned | CC1: Actuals | CD1: Planned | CE1: Actuals | CF1: Planned | CG1: Actuals | CH1: Planned | CI1: Actuals | CJ1: Planned | CK1: Actuals | CL1: Planned | CM1: Planned
E2: 44530 | F2: 44561 | G2: 44592 | H2: 44620 | I2: 44651 | J2: 44681 | K2: 44712 | L2: =EOMONTH(K2,1) -> 44742 | M2: =EOMONTH(L2,1) -> 44773 | N2: =EOMONTH(M2,1) -> 44804 | O2: =EOMONTH(N2,1) -> 44834 | P2: =EOMONTH(O2,1) -> 44865 | Q2: =EOMONTH(P2,1) -> 44895 | R2: =EOMONTH(Q2,1) -> 44926 | S2: =EOMONTH(R2,1) -> 44957 | ... V2: =EOMONTH(U2,1) -> 45046 | W2: =EOMONTH(U2,1) -> 45046 | X2: =EOMONTH(V2,1) -> 45077 | Y2: =EOMONTH(W2,1) -> 45077 | Z2: =EOMONTH(X2,1) -> 45107 | AA2: =EOMONTH(Y2,1) -> 45107 | AB2: =EOMONTH(Z2,1) -> 45138 | AC2: =EOMONTH(AA2,1) -> 45138 | AD2: =EOMONTH(AB2,1) -> 45169 | ... CL2: =EOMONTH(CJ2,1) -> 46081 | CM2: =EOMONTH(CL2,1) -> 46112
C3: Bookings
C4: =SUM(E4:U4)+W4+Y4+AA4+AC4+AE4+AG4+AI4+AK4+AM4+AO4+AQ4+AS4+AU4+AW4+AY4+BA4+BC4+BE4+BG4+BI4+BK4+BM4+BO4+BQ4+BS4+BU4+BW4+BY4+CA4+CC4+CE4+CG4+CI4+CK4 -> 18254652 | D4: Bookings (new customers) $ | E4: =E6+E7 -> 18000 | F4: =F6+F7 -> 27000 | G4: =G6+G7 -> 36000 | H4: =H6+H7 -> 24244 | I4: =I6+I7 -> 21500 | J4: =J6+J7 -> 80112 | K4: =K6+K7 -> 72033.33 | L4: =L6+L7 -> 41800 | ... CM4: =CM6+CM7 -> 682384.85 | CO4: Bookings (new customers) $ | CP4: =D4=CO4 -> TRUE
BG5: =BG4+BE4+BC4 -> 1134783.5 | BM5: =BM4+BK4+BI4 -> 1615813.5 | CP5: =D5=CO5 -> TRUE
C6: =SUM(E6:U6)+W6+Y6+AA6+AC6+AE6+AG6+AI6+AK6+AM6+AO6+AQ6+AS6+AU6+AW6+AY6+BA6+BC6+BE6+BG6+BI6+BK6+BM6+BO6+BQ6+BS6+BU6+BW6+BY6+CA6+CC6+CE6+CG6+CI6+CK6 -> 10466578 | D6: NA/EU | F6: 8000 | G6: 5000 | K6: 9000 | L6: 6500 | N6: 7500 | O6: 19500 | P6: 17400 | Q6: 25000 | R6: 45900 | S6: 20600 | T6: 33500 | U6: 137560 | V6: 158255.66 | W6: 109000 | X6: 154692.24 | Y6: 118390 | Z6: 160450.32 | AA6: 224750 | AB6: 155931.9 | AC6: 123000 | AD6: 182933.97 | AE6: 147875 | AF6: 216485.82 | AG6: 258480 | AH6: 224267.54 | AI6: 180300 | AJ6: 260600.36 | AK6: 156800 | AL6: 293828.25 | AM6: 212700 | AN6: =AN89*12 -> 171000 | AO6: 88000 | AP6: =AP89*12 -> 173430 | AQ6: 150120 | AR6: =AR89*12 -> 246285.6 | AS6: 207800 | AT6: =AT89*12 -> 225048.48 | AU6: 169000 | AV6: =AV89*12 -> 237900.44 | AW6: 287400 | AX6: =AX89*12 -> 222335.45 | AY6: 296550 | AZ6: =AZ89*12 -> 330279.01 | BA6: 201933.33 | BB6: =BB89*12 -> 377705.51 | BC6: 224350 | BD6: =BD89*12 -> 360666.55 | BE6: 272500 | BF6: =BF89*12 -> 382982.39 | BG6: 211050 | BH6: =BH89*12 -> 395356.86 | BI6: 340467 | BJ6: =BJ89*12 -> 437956.35 | BK6: 407800 | BL6: =BL89*12 -> 270886.61 | BM6: 316029 | BN6: =BN89*12 -> 286361.65 | BO6: 522156 | BP6: =BP89*12 -> 309960.92 | BQ6: 408400 | BR6: =BR89*12 -> 341250 | BS6: 311500 | BT6: =BT89*12 -> 328556.25 | BU6: 370540 | BV6: =BV89*12 -> 356228.91 | BW6: 571613 | BX6: =BX89*12 -> 364571.07 | BY6: 375045 | BZ6: =BZ89*12 -> 394883.99 | CA6: 510080 | CB6: =CB89*12 -> 426971.25 | CC6: 432255 | CD6: =CD89*12 -> 416030.93 | CE6: 538840 | CF6: =CF89*12 -> 439370.64 | CG6: 485920 | CH6: =CH89*12 -> 464278 | CI6: 566375 | CJ6: =CJ89*12 -> 490896.25 | CK6: 334100 | CL6: =CL89*12 -> 519381.31 | CM6: =CM89*12 -> 562995.76 | CO6: NA/EU | CP6: =D6=CO6 -> TRUE
A7: xx | C7: =SUM(E7:U7)+W7+Y7+AA7+AC7+AE7+AG7+AI7+AK7+AM7+AO7+AQ7+AS7+AU7+AW7+AY7+BA7+BC7+BE7+BG7+BI7+BK7+BM7+BO7+BQ7+BS7+BU7+BW7+BY7+CA7+CC7+CE7+CG7+CI7+CK7 -> 7788073.2 | D7: India/APAC | E7: 18000 | F7: 19000 | G7: 31000 | H7: 24244 | I7: 21500 | J7: 80112 | K7: 63033.33 | L7: 35300 | M7: 38400 | N7: 103585 | O7: 140643 | P7: 114552.67 | Q7: 96444 | R7: 114900 | S7: 128125 | T7: 158671 | U7: 239315 | V7: 208520 | W7: 149947 | X7: 213358 | Y7: 196220 | Z7: 224670.6 | AA7: 174531.25 | AB7: 223399.87 | AC7: 185095 | AD7: 228609.87 | AE7: 233875 | AF7: 233950.12 | AG7: 169187.5 | AH7: 239423.87 | AI7: 128575 | AJ7: 237845.89 | AK7: 166212.5 | AL7: 243417.04 | AM7: 206225.5 | AN7: =AN104*12 -> 132600 | AO7: 172431 | AP7: =AP104*12 -> 133986 | AQ7: 121764 | AR7: =AR104*12 -> 135386.76 | AS7: 204325 | AT7: =AT104*12 -> 161844.42 | AU7: 175412.75 | AV7: =AV104*12 -> 176209.09 | AW7: 164925 | AX7: =AX104*12 -> 183682.22 | AY7: 204409.5 | AZ7: =AZ104*12 -> 191163.96 | BA7: 170940.5 | BB7: =BB104*12 -> 191754.42 | BC7: 100080 | BD7: =BD104*12 -> 205871.64 | BE7: 221086 | BF7: =BF104*12 -> 220482.72 | BG7: 105717.5 | BH7: =BH104*12 -> 228205.96 | BI7: 162525.68 | BJ7: =BJ104*12 -> 229041.55 | BK7: 256553.44 | BL7: =BL104*12 -> 167316.27 | BM7: 132438.35 | BN7: =BN104*12 -> 173156.02 | BO7: 158773.01 | BP7: =BP104*12 -> 178609.98 | BQ7: 239459.72 | BR7: =BR104*12 -> 178933.93 | BS7: 154297.19 | BT7: =BT104*12 -> 173749.48 | BU7: 244624 | BV7: =BV104*12 -> 120332.96 | BW7: 243284 | BX7: =BX104*12 -> 120577.07 | BY7: 189244 | BZ7: =BZ104*12 -> 116761.32 | CA7: 191789.96 | CB7: =CB104*12 -> 115451.48 | CC7: 241960 | CD7: =CD104*12 -> 101255.19 | CE7: 248966.4 | CF7: =CF104*12 -> 111862.33 | CG7: 209521.32 | CH7: =CH104*12 -> 117412.14 | CI7: 229089 | CJ7: =CJ104*12 -> 113569.26 | CK7: 207762.14 | CL7: =CL104*12 -> 119138 | CM7: =CM104*12 -> 119389.09 | CO7: India/APAC | CP7: =D7=CO7 -> TRUE
CI8: =CI19+CG19+CE19 -> 385761.52 | CP8: =D8=CO8 -> TRUE
C9: =SUM(E9:U9)+W9+Y9+AA9+AC9+AE9+AG9+AI9+AK9+AM9+AO9+AQ9+AS9+AU9+AW9+AY9+BA9+BC9+BE9+BG9+BI9+BK9+BM9+BO9+BQ9+BS9+BU9+BW9+BY9+CA9+CC9+CE9+CG9+CI9+CK9 -> 21019628 | D9: Net ARR (New + Expansion) | E9: =SUM(E11:E12) -> 18000 | F9: =SUM(F11:F12) -> 27000 | G9: =SUM(G11:G12) -> 36000 | H9: =SUM(H11:H12) -> 24244 | I9: =SUM(I11:I12) -> 21500 | J9: =SUM(J11:J12) -> 80112 | K9: =SUM(K11:K12) -> 72033.33 | L9: =SUM(L11:L12) -> 41800 | ... CM9: =SUM(CM11:CM12) -> 913036.42 | CO9: Net ARR (New + Expansion) | CP9: =D9=CO9 -> TRUE
AB10: 22141 | AH10: 18483 | BG10: =BG9+BE9+BC9 -> 1387886.1 | BM10: =BM9+BK9+BI9 -> 1789807.6 | CI10: =CI9+CG9+CE9 -> 2664473.2 | CP10: =D10=CO10 -> TRUE
D11: NA/EU | E11: =E6+E21 -> 0 | F11: =F6+F21 -> 8000 | G11: =G6+G21 -> 5000 | H11: =H6+H21 -> 0 | I11: =I6+I21 -> 0 | J11: =J6+J21 -> 0 | K11: =K6+K21 -> 9000 | L11: =L6+L21 -> 6500 | ... CM11: =CM6+CM21 -> 689264.86 | CO11: NA/EU | CP11: =D11=CO11 -> TRUE
D12: India/APAC | E12: =E7+E22 -> 18000 | F12: =F7+F22 -> 19000 | G12: =G7+G22 -> 31000 | H12: =H7+H22 -> 24244 | I12: =I7+I22 -> 21500 | J12: =J7+J22 -> 80112 | K12: =K7+K22 -> 63033.33 | L12: =L7+L22 -> 35300 | ... CM12: =CM7+CM22 -> 223771.55 | CO12: India/APAC | CP12: =D12=CO12 -> TRUE
CI13: =CI11+CG11+CE11 -> 1769385 | CK13: =CI12+CG12+CE12 -> 895088.24 | CP13: =D13=CO13 -> TRUE
D14: Net New ARR | E14: =E16+E17 -> 18000 | F14: =F16+F17 -> 27000 | G14: =G16+G17 -> 36000 | H14: =H16+H17 -> 24244 | I14: =I16+I17 -> 21500 | J14: =J16+J17 -> 80112 | K14: =K16+K17 -> 72033.33 | L14: =L16+L17 -> 41800 | ... CM14: =CM16+CM17 -> 831413.04 | CO14: Net New ARR | CP14: =D14=CO14 -> TRUE
CP15: =D15=CO15 -> TRUE
D16: NA/EU | E16: =(E95-E88)*12 -> 0 | F16: =(F95-F88)*12 -> 8000 | G16: =(G95-G88)*12 -> 5000 | H16: =(H95-H88)*12 -> 0 | I16: =(I95-I88)*12 -> 0 | J16: =(J95-J88)*12 -> 0 | K16: =(K95-K88)*12 -> 9000 | L16: =(L95-L88)*12 -> 6500 | ... CM16: =(CM95-CM88)*12 -> 652317.55 | CO16: NA/EU | CP16: =D16=CO16 -> TRUE
D17: India/APAC | E17: =(E110-E103)*12 -> 18000 | F17: =(F110-F103)*12 -> 19000 | G17: =(G110-G103)*12 -> 31000 | H17: =(H110-H103)*12 -> 24244 | I17: =(I110-I103)*12 -> 21500 | J17: =(J110-J103)*12 -> 80112 | K17: =(K110-K103)*12 -> 63033.33 | L17: =(L110-L103)*12 -> 35300 | ... CM17: =(CM110-CM103)*12 -> 179095.49 | CO17: India/APAC | CP17: =D17=CO17 -> TRUE
CP18: =D18=CO18 -> TRUE
C19: =SUM(E19:U19)+W19+Y19+AA19+AC19+AE19+AG19+AI19+AK19+AM19+AO19+AQ19+AS19+AU19+AW19+AY19+BA19+BC19+BE19+BG19+BI19+BK19+BM19+BO19+BQ19+BS19+BU19+BW19+BY19+CA19+CC19+CE19+CG19+CI19+CK19 -> 2764976.6 | D19: Expansion | E19: =E21+E22 -> 0 | F19: =F21+F22 -> 0 | G19: =G21+G22 -> 0 | H19: =H21+H22 -> 0 | I19: =I21+I22 -> 0 | J19: =J21+J22 -> 0 | K19: =K21+K22 -> 0 | L19: =L21+L22 -> 0 | ... CM19: =CM21+CM22 -> 230651.57 | CO19: Expansion | CP19: =D19=CO19 -> TRUE
BI20: =BI19+BI24 -> 54989.203 | BJ20: =BJ19+BJ24 -> 91525.917 | BK20: =BK19+BK24 -> 67573.808 | BL20: =BL19+BL24 -> 101508.12 | BM20: =BM19+BM24 -> 57990.76 | BN20: =BN19+BN24 -> 108998.23 | BO20: =BO19+BO24 -> 79131.497 | BP20: =BP19+BP24 -> 113385.58 | ... CE20: =CE19+CE24 -> 116652.97 | CP20: =D20=CO20 -> TRUE
A21: x | C21: =SUM(E21:U21)+W21+Y21+AA21+AC21+AE21+AG21+AI21+AK21+AM21+AO21+AQ21+AS21+AU21+AW21+AY21+BA21+BC21+BE21+BG21+BI21+BK21+BM21+BO21+BQ21+BS21+BU21+BW21+BY21+CA21+CC21+CE21+CG21+CI21+CK21 -> 985029.24 | D21: NA/EU | E21: 0 | F21: 0 | G21: 0 | H21: 0 | I21: 0 | J21: 0 | K21: 0 | L21: 0 | M21: 0 | N21: 0 | O21: 0 | P21: 0 | Q21: 0 | R21: 0 | S21: 0 | T21: 0 | U21: 6000 | V21: =V90*12 -> 250 | W21: 0 | X21: =X90*12 -> 161.25 | Y21: 0 | Z21: =Z90*12 -> 0 | AA21: 3500 | AB21: =AB90*12 -> 372.68906 | AC21: 10000 | AD21: =AD90*12 -> 1034.9886 | AE21: 26200 | AF21: =AF90*12 -> 929.56999 | AG21: 1000 | AH21: =AH90*12 -> 0 | AI21: 1500 | AJ21: =AJ90*12 -> 0 | AK21: 4000 | AL21: =AL90*12 -> 0 | AM21: 4100 | AN21: =AN90*12 -> 8000 | AO21: 23000 | AP21: =AP90*12 -> 8300 | AQ21: 6000 | AR21: =AR90*12 -> 8612 | AS21: 13500 | AT21: =AT90*12 -> 8936.51 | AU21: 17000 | AV21: =AV90*12 -> 9274.0628 | AW21: 26500 | AX21: =AX90*12 -> 9625.2151 | AY21: 25006 | AZ21: =AZ90*12 -> 14010.835 | BA21: 49500 | BB21: =BB90*12 -> 14591.972 | BC21: 25000 | BD21: =BD90*12 -> 15198.583 | BE21: 21800 | BF21: =BF90*12 -> 20485.82 | BG21: 47500 | BH21: =BH90*12 -> 21379.634 | BI21: 7500 | BJ21: =BJ90*12 -> 29235.393 | BK21: 22018.24 | BL21: =BL90*12 -> 20180.541 | BM21: 2500 | BN21: =BN90*12 -> 24289.299 | BO21: 25000 | BP21: =BP90*12 -> 28422.528 | BQ21: 79250 | BR21: =BR90*12 -> 28507.795 | BS21: 16600 | BT21: =BT90*12 -> 36762.838 | BU21: 18750 | BV21: =BV90*12 -> 36873.127 | BW21: 66500 | BX21: =BX90*12 -> 45202.356 | BY21: 51295 | BZ21: =BZ90*12 -> 49459.596 | CA21: 43600 | CB21: =CB90*12 -> 62009.969 | CC21: 80975 | CD21: =CD90*12 -> 62195.999 | CE21: 60450 | CF21: =CF90*12 -> 74859.104 | CG21: 62200 | CH21: =CH90*12 -> 83426.313 | CI21: 55600 | CJ21: =CJ90*12 -> 92044.251 | CK21: 81685 | CL21: =CL90*12 -> 109105.91 | CM21: =CM90*12 -> 126269.11 | CO21: NA/EU | CP21: =D21=CO21 -> TRUE
A22: xx | C22: =SUM(E22:U22)+W22+Y22+AA22+AC22+AE22+AG22+AI22+AK22+AM22+AO22+AQ22+AS22+AU22+AW22+AY22+BA22+BC22+BE22+BG22+BI22+BK22+BM22+BO22+BQ22+BS22+BU22+BW22+BY22+CA22+CC22+CE22+CG22+CI22+CK22 -> 1779947.3 | D22: India/APAC | E22: 0 | F22: 0 | G22: 0 | H22: 0 | I22: 0 | J22: 0 | K22: 0 | L22: 0 | M22: 0 | N22: 0 | O22: 2380 | P22: 2000 | Q22: 0 | R22: 4533 | S22: 2500 | T22: 3350 | U22: 14250 | V22: =V105*12 -> 3705 | W22: 19375 | X22: =X105*12 -> 5011.2738 | Y22: 39810 | Z22: =Z105*12 -> 3757.3991 | AA22: 45550 | AB22: =AB105*12 -> 3298.174 | AC22: 13465 | AD22: =AD105*12 -> 11113.106 | AE22: 33075 | AF22: =AF105*12 -> 7146.0632 | AG22: 24237.5 | AH22: =AH105*12 -> 7737.6472 | AI22: 40896 | AJ22: =AJ105*12 -> 9102.9793 | AK22: 38887.5 | AL22: =AL105*12 -> 10079.274 | AM22: 54382.15 | AN22: =AN105*12 -> 33000 | AO22: 40308.33 | AP22: =AP105*12 -> 36050 | AQ22: 50536 | AR22: =AR105*12 -> 37131.5 | AS22: 23250 | AT22: =AT105*12 -> 38245.445 | AU22: 62912.5 | AV22: =AV105*12 -> 39392.808 | AW22: 88944 | AX22: =AX105*12 -> 44052.415 | AY22: 47825 | AZ22: =AZ105*12 -> 47762.092 | BA22: 51679 | BB22: =BB105*12 -> 49194.955 | BC22: 61397 | BD22: =BD105*12 -> 50670.803 | BE22: 56343 | BF22: =BF105*12 -> 54800.474 | BG22: 41062.64 | BH22: =BH105*12 -> 56444.488 | BI22: 46589.203 | BJ22: =BJ105*12 -> 62290.524 | BK22: 42340.568 | BL22: =BL105*12 -> 81327.578 | BM22: 53046.072 | BN22: =BN105*12 -> 84708.929 | BO22: 50470.247 | BP22: =BP105*12 -> 84963.056 | BQ22: 65498.88 | BR22: =BR105*12 -> 88374.165 | BS22: 57345.786 | BT22: =BT105*12 -> 88639.287 | BU22: 58456 | BV22: =BV105*12 -> 92080.391 | BW22: 83316.4 | BX22: =BX105*12 -> 92356.632 | BY22: 53964.8 | BZ22: =BZ105*12 -> 92633.702 | CA22: 59601 | CB22: =CB105*12 -> 99319.3 | CC22: 104729.05 | CD22: =CD105*12 -> 99617.258 | CE22: 37352.04 | CF22: =CF105*12 -> 99916.11 | CG22: 87759 | CH22: =CH105*12 -> 100215.86 | CI22: 82400.48 | CJ22: =CJ105*12 -> 103758.97 | CK22: 34129.2 | CL22: =CL105*12 -> 104070.25 | CM22: =CM105*12 -> 104382.46 | CO22: India/APAC | CP22: =D22=CO22 -> TRUE
CE23: =CE20+CC20+CA20+BY20+BW20+BU20+BS20+BQ20+BO20+BM20+BK20+BI20 -> 1295229.9 | CP23: =D23=CO23 -> TRUE
C24: =SUM(E24:U24)+W24+Y24+AA24+AC24+AE24+AG24+AI24+AK24+AM24+AO24+AQ24+AS24+AU24+AW24+AY24+BA24+BC24+BE24+BG24+BI24+BK24+BM24+BO24+BQ24+BS24+BU24+BW24+BY24+CA24+CC24+CE24+CG24+CI24+CK24 -> 156076.82 | D24: Revenue Expansion | E24: =E26+E27 -> 0 | F24: =F26+F27 -> 0 | G24: =G26+G27 -> 0 | H24: =H26+H27 -> 0 | I24: =I26+I27 -> 0 | J24: =J26+J27 -> 0 | K24: =K26+K27 -> 0 | L24: =L26+L27 -> 0 | ... U24: =U26+U27 -> 0 | V24: 0 | W24: =W26+W27 -> 0 | X24: 0 | Y24: =Y26+Y27 -> 0 | Z24: 0 | AA24: =AA26+AA27 -> 1500 | AB24: 0 | AC24: =AC26+AC27 -> 0 | AD24: 0 | AE24: =AE26+AE27 -> 0 | AF24: 0 | AG24: =AG26+AG27 -> 0 | AH24: 0 | AI24: =AI26+AI27 -> 0 | AJ24: 0 | AK24: =AK26+AK27 -> 0 | AL24: 0 | AM24: =AM26+AM27 -> 563 | AN24: 0 | AO24: =AO26+AO27 -> 473 | AP24: 0 | AQ24: =AQ26+AQ27 -> 150 | AR24: 0 | AS24: =AS26+AS27 -> 0 | AT24: 0 | AU24: =AU26+AU27 -> 5325 | AV24: 0 | AW24: =AW26+AW27 -> 2587.5 | AX24: 0 | AY24: =AY26+AY27 -> 6522.5 | AZ24: 0 | BA24: =BA26+BA27 -> 2862.5 | BB24: 0 | BC24: =BC26+BC27 -> 4696.875 | BD24: 0 | BE24: =BE26+BE27 -> 2682.5 | BF24: 0 | BG24: =BG26+BG27 -> 2437.5 | BH24: 0 | BI24: =BI26+BI27 -> 900 | BJ24: 0 | BK24: =BK26+BK27 -> 3215 | BL24: 0 | BM24: =BM26+BM27 -> 2444.6875 | BN24: 0 | BO24: =BO26+BO27 -> 3661.25 | BP24: 0 | BQ24: =BQ26+BQ27 -> 3172.5 | BR24: 0 | BS24: =BS26+BS27 -> 6575 | BT24: 0 | BU24: =BU26+BU27 -> 9924.375 | BV24: 0 | BW24: =BW26+BW27 -> 21371.737 | BX24: 0 | BY24: =BY26+BY27 -> 14000 | BZ24: 0 | CA24: =CA26+CA27 -> 6918.175 | CB24: 0 | CC24: =CC26+CC27 -> 17047.969 | CD24: 0 | CE24: =CE26+CE27 -> 18850.93 | CF24: 0 | CG24: =CG26+CG27 -> 3898.0817 | CH24: 0 | CI24: =CI26+CI27 -> 4010 | CJ24: 0 | CK24: =CK26+CK27 -> 10286.74 | CL24: 0 | CM24: 0 | CO24: Revenue Expansion | CP24: =D24=CO24 -> TRUE
CP25: =D25=CO25 -> TRUE
C26: =SUM(E26:U26)+W26+Y26+AA26+AC26+AE26+AG26+AI26+AK26+AM26+AO26+AQ26+AS26+AU26+AW26+AY26+BA26+BC26+BE26+BG26+BI26+BK26+BM26+BO26+BQ26+BS26+BU26+BW26+BY26+CA26+CC26+CE26+CG26+CI26+CK26 -> 104108.74 | D26: NA/EU | E26: 0 | F26: 0 | G26: 0 | H26: 0 | I26: 0 | J26: 0 | K26: 0 | L26: 0 | M26: 0 | N26: 0 | O26: 0 | P26: 0 | Q26: 0 | R26: 0 | S26: 0 | T26: 0 | U26: 0 | V26: 0 | W26: 0 | X26: 0 | Y26: 0 | Z26: 0 | AA26: 1500 | AB26: 0 | AC26: 0 | AD26: 0 | AE26: 0 | AF26: 0 | AG26: 0 | AH26: 0 | AI26: 0 | AJ26: 0 | AK26: 0 | AL26: 0 | AM26: 0 | AN26: 0 | AO26: 0 | AP26: 0 | AR26: 0 | AS26: 0 | AT26: 0 | AU26: 2325 | AV26: 0 | AW26: 1537.5 | AX26: 0 | AY26: 5310 | AZ26: 0 | BA26: 1600 | BB26: 0 | BC26: 2490 | BD26: 0 | BE26: 2330 | BF26: 0 | BG26: 1800 | BH26: 0 | BJ26: 0 | BK26: 3215 | BL26: 0 | BM26: 1352.5 | BN26: 0 | BO26: 2436 | BP26: 0 | BQ26: 3172.5 | BR26: 0 | BS26: 5825 | BT26: 0 | BU26: 6097.5 | BV26: 0 | BW26: 13455.45 | BX26: 0 | BY26: 10472.5 | BZ26: 0 | CA26: 5342.5 | CB26: 0 | CC26: 7452.5 | CD26: 0 | CE26: 13054.75 | CF26: 0 | CG26: 1528.8 | CH26: 0 | CI26: 3310 | CJ26: 0 | CK26: 8501.24 | CL26: 0 | CM26: 0 | CO26: NA/EU | CP26: =D26=CO26 -> TRUE
C27: =SUM(E27:U27)+W27+Y27+AA27+AC27+AE27+AG27+AI27+AK27+AM27+AO27+AQ27+AS27+AU27+AW27+AY27+BA27+BC27+BE27+BG27+BI27+BK27+BM27+BO27+BQ27+BS27+BU27+BW27+BY27+CA27+CC27+CE27+CG27+CI27+CK27 -> 51968.081 | D27: India/APAC | E27: 0 | F27: 0 | G27: 0 | H27: 0 | I27: 0 | J27: 0 | K27: 0 | L27: 0 | M27: 0 | N27: 0 | O27: 0 | P27: 0 | Q27: 0 | R27: 0 | S27: 0 | T27: 0 | U27: 0 | V27: 0 | W27: 0 | X27: 0 | Y27: 0 | Z27: 0 | AA27: 0 | AB27: 0 | AC27: 0 | AD27: 0 | AE27: 0 | AF27: 0 | AG27: 0 | AH27: 0 | AI27: 0 | AJ27: 0 | AK27: 0 | AL27: 0 | AM27: 563 | AN27: 0 | AO27: 473 | AP27: 0 | AQ27: 150 | AR27: 0 | AS27: 0 | AT27: 0 | AU27: 3000 | AV27: 0 | AW27: 1050 | AX27: 0 | AY27: 1212.5 | AZ27: 0 | BA27: 1262.5 | BB27: 0 | BC27: 2206.875 | BD27: 0 | BE27: 352.5 | BF27: 0 | BG27: 637.5 | BH27: 0 | BI27: 900 | BJ27: 0 | BL27: 0 | BM27: 1092.1875 | BN27: 0 | BO27: 1225.25 | BP27: 0 | BR27: 0 | BS27: 750 | BT27: 0 | BU27: 3826.875 | BV27: 0 | BW27: 7916.2875 | BX27: 0 | BY27: 3527.5 | BZ27: 0 | CA27: 1575.675 | CB27: 0 | CC27: 9595.469 | CD27: 0 | CE27: 5796.18 | CF27: 0 | CG27: 2369.2817 | CH27: 0 | CI27: 700 | CJ27: 0 | CK27: 1785.5 | CL27: 0 | CM27: 0 | CO27: India/APAC | CP27: =D27=CO27 -> TRUE
CP28: =D28=CO28 -> TRUE
C29: =SUM(E29:U29)+W29+Y29+AA29+AC29+AE29+AG29+AI29+AK29+AM29+AO29+AQ29+AS29+AU29+AW29+AY29+BA29+BC29+BE29+BG29+BI29+BK29+BM29+BO29+BQ29+BS29+BU29+BW29+BY29+CA29+CC29+CE29+CG29+CI29+CK29 -> 3584579.5 | D29: Logo Churn | E29: =SUM(E31:E32) -> 0 | F29: =SUM(F31:F32) -> 0 | G29: =SUM(G31:G32) -> 0 | H29: =SUM(H31:H32) -> 0 | I29: =SUM(I31:I32) -> 0 | J29: =SUM(J31:J32) -> 0 | K29: =SUM(K31:K32) -> 0 | L29: =SUM(L31:L32) -> 0 | ... CM29: =SUM(CM31:CM32) -> 81623.376 | CO29: Logo Churn | CP29: =D29=CO29 -> TRUE
BI30: =BI29+BI34 -> 141515.5 | BK30: =BK29+BK34 -> 119395 | BM30: =BM29+BM34 -> 111955 | BO30: =BO29+BO34 -> 186375 | BQ30: =BQ29+BQ34 -> 410620.33 | BS30: =BS29+BS34 -> 158861 | BU30: =BU29+BU34 -> 30326.4 | BW30: =BW29+BW34 -> 218023 | BY30: =BY29+BY34 -> 185123.5 | CA30: =CA29+CA34 -> 234320 | CC30: =CC29+CC34 -> 270812.94 | CE30: =CE29+CE34 -> 412544.22 | CP30: =D30=CO30 -> TRUE
C31: =SUM(E31:U31)+W31+Y31+AA31+AC31+AE31+AG31+AI31+AK31+AM31+AO31+AQ31+AS31+AU31+AW31+AY31+BA31+BC31+BE31+BG31+BI31+BK31+BM31+BO31+BQ31+BS31+BU31+BW31+BY31+CA31+CC31+CE31+CG31+CI31+CK31 -> 1497526 | D31: NA/EU | E31: 0 | F31: 0 | G31: 0 | H31: 0 | I31: 0 | J31: 0 | K31: 0 | L31: 0 | M31: 0 | N31: 0 | O31: 0 | P31: 0 | Q31: 0 | R31: 0 | S31: 0 | T31: 0 | U31: 0 | V31: =-V92*12 -> 750 | W31: 0 | X31: =-X92*12 -> 450 | Y31: 0 | Z31: =-Z92*12 -> 0 | AA31: 6600 | AB31: =-AB92*12 -> 900 | AC31: 0 | AD31: =-AD92*12 -> 2325 | AE31: 0 | AF31: =-AF92*12 -> 647.5 | AG31: 5000 | AH31: =-AH92*12 -> 0 | AI31: 8000 | AJ31: =-AJ92*12 -> 0 | AK31: 50840 | AL31: =-AL92*12 -> 0 | AM31: 18000 | AN31: =-AN92*12 -> 22823.244 | AO31: 0 | AP31: =-AP92*12 -> 24697.365 | AQ31: 16000 | AR31: =-AR92*12 -> 26581.757 | AS31: 21000 | AT31: =-AT92*12 -> 26878.085 | AU31: 20000 | AV31: =-AV92*12 -> 29156.261 | AW31: 10000 | AX31: =-AX92*12 -> 31554.461 | AY31: 0 | AZ31: =-AZ92*12 -> 24551.949 | BA31: 16500 | BB31: =-BB92*12 -> 16943.657 | BC31: 30500 | BD31: =-BD92*12 -> 18820.426 | BE31: 14000 | BF31: =-BF92*12 -> 20605.65 | BG31: 20000 | BH31: =-BH92*12 -> 22519.963 | BI31: 47200 | BJ31: =-BJ92*12 -> 24491.045 | BK31: 63000 | BL31: =-BL92*12 -> 14278.17 | BM31: 13300 | BN31: =-BN92*12 -> 15108.537 | BO31: 84000 | BP31: =-BP92*12 -> 15995.164 | BQ31: 151866 | BR31: =-BR92*12 -> 28270.548 | BS31: 63500 | BT31: =-BT92*12 -> 29977.984 | BU31: 7000 | BV31: =-BV92*12 -> 31654.69 | BW31: 96950 | BX31: =-BX92*12 -> 23423.349 | BY31: 54870 | BZ31: =-BZ92*12 -> 24775.574 | CA31: 129910 | CB31: =-CB92*12 -> 26244.062 | CC31: 148350 | CD31: =-CD92*12 -> 27863.642 | CE31: 202080 | CF31: =-CF92*12 -> 29439.913 | CG31: 42660 | CH31: =-CH92*12 -> 31136.678 | CI31: 95850 | CJ31: =-CJ92*12 -> 32944.665 | CK31: 60550 | CL31: =-CL92*12 -> 34869.65 | CM31: =-CM92*12 -> 36947.312 | CO31: NA/EU | CP31: =D31=CO31 -> TRUE
C32: =SUM(E32:U32)+W32+Y32+AA32+AC32+AE32+AG32+AI32+AK32+AM32+AO32+AQ32+AS32+AU32+AW32+AY32+BA32+BC32+BE32+BG32+BI32+BK32+BM32+BO32+BQ32+BS32+BU32+BW32+BY32+CA32+CC32+CE32+CG32+CI32+CK32 -> 2087053.5 | D32: India/APAC | E32: 0 | F32: 0 | G32: 0 | H32: 0 | I32: 0 | J32: 0 | K32: 0 | L32: 0 | M32: 0 | N32: 0 | O32: 0 | P32: 0 | Q32: 12000 | R32: 15000 | S32: 4000 | T32: 4500 | U32: 5500 | V32: =-V107*12 -> 11115 | W32: 33000 | X32: =-X107*12 -> 13984.95 | Y32: 22000 | Z32: =-Z107*12 -> 9754.2 | AA32: 4000 | AB32: =-AB107*12 -> 7964.7 | AC32: 28660 | AD32: =-AD107*12 -> 24964.5 | AE32: 9000 | AF32: =-AF107*12 -> 4977.652 | AG32: 40300 | AH32: =-AH107*12 -> 4888.3552 | AI32: 35666.67 | AJ32: =-AJ107*12 -> 5215.9514 | AK32: 58665 | AL32: =-AL107*12 -> 5238.1192 | AM32: 63039.25 | AN32: =-AN107*12 -> 89300.31 | AO32: 43225 | AP32: =-AP107*12 -> 91398.551 | AQ32: 58771 | AR32: =-AR107*12 -> 93561.081 | AS32: 81375 | AT32: =-AT107*12 -> 95732.404 | AU32: 25418.65 | AV32: =-AV107*12 -> 98602.234 | AW32: 53250 | AX32: =-AX107*12 -> 101819.72 | AY32: 6250 | AZ32: =-AZ107*12 -> 72740.557 | BA32: 74511 | BB32: =-BB107*12 -> 39946.358 | BC32: 48425 | BD32: =-BD107*12 -> 41956.389 | BE32: 65925 | BF32: =-BF107*12 -> 44102.249 | BG32: 67675 | BH32: =-BH107*12 -> 46414.059 | BI32: 69931 | BJ32: =-BJ107*12 -> 48796.423 | BK32: 54395 | BL32: =-BL107*12 -> 48952.643 | BM32: 91300 | BN32: =-BN107*12 -> 50949.555 | BO32: 97375 | BP32: =-BP107*12 -> 53018.709 | BQ32: 155434.33 | BR32: =-BR107*12 -> 44099.401 | BS32: 40413 | BT32: =-BT107*12 -> 45885.071 | BU32: 15826.4 | BV32: =-BV107*12 -> 47617.101 | BW32: 117060 | BX32: =-BX107*12 -> 48935.471 | BY32: 100590.5 | BZ32: =-BZ107*12 -> 50247.456 | CA32: 87045 | CB32: =-CB107*12 -> 51520.637 | CC32: 75725 | CD32: =-CD107*12 -> 46223.308 | CE32: 138268.2 | CF32: =-CF107*12 -> 47305.852 | CG32: 54268 | CH32: =-CH107*12 -> 48457.16 | CI32: 65384.28 | CJ32: =-CJ107*12 -> 42549.734 | CK32: 63881.196 | CL32: =-CL107*12 -> 43598.405 | CM32: =-CM107*12 -> 44676.064 | CO32: India/APAC | CP32: =D32=CO32 -> TRUE
CE33: =CE30+CC30+CA30+BY30+BW30+BU30+BS30+BQ30+BO30+BM30+BK30+BI30 -> 2479871.9 | CP33: =D33=CO33 -> TRUE
C34: =SUM(E34:U34)+W34+Y34+AA34+AC34+AE34+AG34+AI34+AK34+AM34+AO34+AQ34+AS34+AU34+AW34+AY34+BA34+BC34+BE34+BG34+BI34+BK34+BM34+BO34+BQ34+BS34+BU34+BW34+BY34+CA34+CC34+CE34+CG34+CI34+CK34 -> 494513.7 | D34: Revenue Churn | E34: =SUM(E36:E37) -> 0 | F34: =SUM(F36:F37) -> 0 | G34: =SUM(G36:G37) -> 0 | H34: =SUM(H36:H37) -> 0 | I34: =SUM(I36:I37) -> 0 | J34: =SUM(J36:J37) -> 0 | K34: =SUM(K36:K37) -> 0 | L34: =SUM(L36:L37) -> 0 | ... CM34: =SUM(CM36:CM37) -> 0 | CO34: Revenue Churn | CP34: =D34=CO34 -> TRUE
CG35: =CE29+CG29+CI29+CE34+CG34+CI34 -> 701731.31 | CP35: =D35=CO35 -> TRUE
C36: =SUM(E36:U36)+W36+Y36+AA36+AC36+AE36+AG36+AI36+AK36+AM36+AO36+AQ36+AS36+AU36+AW36+AY36+BA36+BC36+BE36+BG36+BI36+BK36+BM36+BO36+BQ36+BS36+BU36+BW36+BY36+CA36+CC36+CE36+CG36+CI36+CK36 -> 110371.93 | D36: NA/EU | E36: 0 | F36: 0 | G36: 0 | H36: 0 | I36: 0 | J36: 0 | K36: 0 | L36: 0 | M36: 0 | N36: 0 | O36: 0 | P36: 0 | Q36: 0 | R36: 0 | S36: 0 | T36: 0 | U36: 0 | V36: =-V93*12 -> 0 | W36: 0 | X36: =-X93*12 -> 0 | Y36: 0 | Z36: =-Z93*12 -> 0 | AA36: 0 | AB36: =-AB93*12 -> 0 | AC36: 0 | AD36: =-AD93*12 -> 0 | AE36: 0 | AF36: =-AF93*12 -> 0 | AG36: 0 | AH36: =-AH93*12 -> 0 | AI36: 2000 | AJ36: =-AJ93*12 -> 0 | AK36: 0 | AL36: =-AL93*12 -> 0 | AM36: 0 | AN36: =-AN93*12 -> 0 | AO36: 833 | AP36: =-AP93*12 -> 0 | AQ36: 0 | AR36: =-AR93*12 -> 0 | AS36: 300 | AT36: =-AT93*12 -> 0 | AU36: 0 | AV36: =-AV93*12 -> 0 | AW36: 0 | AX36: =-AX93*12 -> 0 | AY36: 0 | AZ36: =-AZ93*12 -> 0 | BA36: 0 | BB36: =-BB93*12 -> 0 | BC36: 0 | BD36: =-BD93*12 -> 0 | BE36: 0 | BF36: =-BF93*12 -> 0 | BG36: 0 | BH36: =-BH93*12 -> 0 | BI36: 4500 | BJ36: =-BJ93*12 -> 0 | BK36: 2000 | BL36: =-BL93*12 -> 0 | BM36: 0 | BN36: =-BN93*12 -> 0 | BO36: 0 | BP36: =-BP93*12 -> 0 | BQ36: 9750 | BR36: =-BR93*12 -> 0 | BS36: 12600 | BT36: =-BT93*12 -> 0 | BU36: 0 | BV36: =-BV93*12 -> 0 | BW36: 0 | BX36: =-BX93*12 -> 0 | BY36: 8500 | BZ36: =-BZ93*12 -> 0 | CA36: 10000 | CB36: =-CB93*12 -> 0 | CC36: 11981.425 | CD36: =-CD93*12 -> 0 | CE36: 29300 | CF36: =-CF93*12 -> 0 | CG36: 7087.5 | CH36: =-CH93*12 -> 0 | CI36: 3000 | CJ36: =-CJ93*12 -> 0 | CK36: 8520 | CL36: =-CL93*12 -> 0 | CM36: =-CM93*12 -> 0 | CO36: NA/EU | CP36: =D36=CO36 -> TRUE
C37: =SUM(E37:U37)+W37+Y37+AA37+AC37+AE37+AG37+AI37+AK37+AM37+AO37+AQ37+AS37+AU37+AW37+AY37+BA37+BC37+BE37+BG37+BI37+BK37+BM37+BO37+BQ37+BS37+BU37+BW37+BY37+CA37+CC37+CE37+CG37+CI37+CK37 -> 384141.77 | D37: India/APAC | E37: 0 | F37: 0 | G37: 0 | H37: 0 | I37: 0 | J37: 0 | K37: 0 | L37: 0 | M37: 0 | N37: 0 | O37: 0 | P37: 0 | Q37: 561 | R37: 0 | S37: 1500 | T37: 0 | U37: 0 | V37: =-V108*12 -> 0 | W37: 5789 | X37: =-X108*12 -> 0 | Y37: 3500 | Z37: =-Z108*12 -> 0 | AA37: 1000 | AB37: =-AB108*12 -> 0 | AC37: 1452 | AD37: =-AD108*12 -> 0 | AE37: 7300 | AF37: =-AF108*12 -> 0 | AG37: 4034 | AH37: =-AH108*12 -> 0 | AI37: 4854 | AJ37: =-AJ108*12 -> 0 | AK37: 6231 | AL37: =-AL108*12 -> 0 | AM37: 6000 | AN37: =-AN108*12 -> 0 | AO37: 5111.5 | AP37: =-AP108*12 -> 0 | AQ37: 7100 | AR37: =-AR108*12 -> 0 | AS37: 0 | AT37: =-AT108*12 -> 0 | AU37: 0 | AV37: =-AV108*12 -> 0 | AW37: 0 | AX37: =-AX108*12 -> 0 | AY37: 0 | AZ37: =-AZ108*12 -> 0 | BA37: 1125 | BB37: =-BB108*12 -> 0 | BC37: 0 | BD37: =-BD108*12 -> 0 | BE37: 0 | BF37: =-BF108*12 -> 0 | BG37: 5500 | BH37: =-BH108*12 -> 0 | BI37: 19884.5 | BJ37: =-BJ108*12 -> 0 | BK37: 0 | BL37: =-BL108*12 -> 0 | BM37: 7355 | BN37: =-BN108*12 -> 0 | BO37: 5000 | BP37: =-BP108*12 -> 0 | BQ37: 93570 | BR37: =-BR108*12 -> 0 | BS37: 42348 | BT37: =-BT108*12 -> 0 | BU37: 7500 | BV37: =-BV108*12 -> 0 | BW37: 4013 | BX37: =-BX108*12 -> 0 | BY37: 21163 | BZ37: =-BZ108*12 -> 0 | CA37: 7365 | CB37: =-CB108*12 -> 0 | CC37: 34756.519 | CD37: =-CD108*12 -> 0 | CE37: 42896.022 | CF37: =-CF108*12 -> 0 | CG37: 6541.232 | CH37: =-CH108*12 -> 0 | CI37: 14396.08 | CJ37: =-CJ108*12 -> 0 | CK37: 16295.92 | CL37: =-CL108*12 -> 0 | CM37: =-CM108*12 -> 0 | CO37: India/APAC | CP37: =D37=CO37 -> TRUE
CP38: =D38=CO38 -> TRUE
C39: =SUM(E39:U39)+W39+Y39+AA39+AC39+AE39+AG39+AI39+AK39+AM39+AO39+AQ39+AS39+AU39+AW39+AY39+BA39+BC39+BE39+BG39+BI39+BK39+BM39+BO39+BQ39+BS39+BU39+BW39+BY39+CA39+CC39+CE39+CG39+CI39+CK39 -> 298742.54 | D39: One time revenue booked for the month (GMV) | M39: 2000 | N39: 783 | O39: 1280 | P39: 3530 | Q39: 5842 | R39: 2709 | S39: 2000 | T39: 0 | U39: 5775 | V39: 0 | W39: 16091 | X39: 0 | Y39: 925 | Z39: 0 | AA39: 4250 | AB39: 0 | AC39: 1075 | AD39: 0 | AE39: 1000 | AF39: 0 | AG39: 2775 | AH39: 0 | AI39: 5300 | AJ39: 0 | AK39: 250 | AL39: 0 | AM39: 8283.41 | AN39: 0 | AO39: 7742.5 | AP39: 0 | AQ39: 1625 | AR39: 0 | AS39: 19010 | AT39: 0 | AU39: 9075 | AV39: 0 | AW39: 14833.75 | AX39: 0 | AY39: 3600 | AZ39: 0 | BA39: 9900 | BB39: 0 | BC39: 3820 | BD39: 0 | BE39: 11692 | BF39: 0 | BG39: 3650 | BH39: 0 | BI39: 9390 | BJ39: 0 | BK39: 5800 | BL39: 0 | BM39: 8243.556 | BN39: 0 | BO39: 15158.63 | BP39: 0 | BQ39: 5138 | BR39: 0 | BS39: 11941.38 | BT39: 0 | BU39: 6000 | BV39: 0 | BW39: 8717.91 | BX39: 0 | BY39: 7300 | BZ39: 0 | CA39: 8785 | CB39: 0 | CC39: 20341 | CD39: 0 | CE39: 8342 | CF39: 0 | CG39: 10500 | CH39: 0 | CI39: 11768.4 | CJ39: 0 | CK39: 12500 | CL39: 0 | CM39: 0 | CO39: One time revenue booked for the month (GMV) | CP39: =D39=CO39 -> TRUE
CP40: =D40=CO40 -> TRUE
...

Sheet 2. Financial Metrics Actual Aud
E1: Particulars | F1: 44530 | G1: =EOMONTH(F1,1) -> 44561 | H1: =EOMONTH(G1,1) -> 44592 | I1: =EOMONTH(H1,1) -> 44620 | J1: =EOMONTH(I1,1) -> 44651 | K1: =EOMONTH(J1,1) -> 44681 | L1: =EOMONTH(K1,1) -> 44712 | M1: =EOMONTH(L1,1) -> 44742 | N1: =EOMONTH(M1,1) -> 44773 | ... V1: =EOMONTH(U1,1) -> 45016 | W1: 45046 | X1: =W1 -> 45046 | Y1: 45076 | Z1: =EOMONTH(X1,1) -> 45077 | AA1: 45107 | AB1: =AA1 -> 45107 | AC1: 45137 | AD1: =EOMONTH(AB1,1) -> 45138 | AE1: 45168 | AF1: =EOMONTH(AD1,1) -> 45169 | AG1: 45199 | AH1: =EOMONTH(AF1,1) -> 45199 | AI1: 45229 | AJ1: =EOMONTH(AH1,1) -> 45230 | AK1: 45260 | AL1: =EOMONTH(AJ1,1) -> 45260 | AM1: 45290 | AN1: =EOMONTH(AL1,1) -> 45291 | AO1: 45321 | AP1: =EOMONTH(AN1,1) -> 45322 | AQ1: 45351 | AR1: =EOMONTH(AP1,1) -> 45351 | AS1: 45380 | AT1: =EOMONTH(AR1,1) -> 45382 | AU1: =EOMONTH(AS1,1) -> 45412 | AV1: =AU1 -> 45412 | AW1: =EOMONTH(AU1,1) -> 45443 | AX1: =AW1 -> 45443 | AY1: =EOMONTH(AW1,1) -> 45473 | AZ1: =AY1 -> 45473 | BA1: =EOMONTH(AY1,1) -> 45504 | BB1: =BA1 -> 45504 | BC1: =EOMONTH(BA1,1) -> 45535 | BD1: =BC1 -> 45535 | BE1: =EOMONTH(BC1,1) -> 45565 | BF1: =BE1 -> 45565 | BG1: =EOMONTH(BE1,1) -> 45596 | BH1: =BG1 -> 45596 | BI1: =EOMONTH(BG1,1) -> 45626 | BJ1: =BI1 -> 45626 | BK1: =EOMONTH(BI1,1) -> 45657 | BL1: =BK1 -> 45657 | BM1: =EOMONTH(BK1,1) -> 45688 | BN1: =BM1 -> 45688 | BO1: =EOMONTH(BM1,1) -> 45716 | BP1: =BO1 -> 45716 | BQ1: =EOMONTH(BO1,1) -> 45747 | BR1: =BQ1 -> 45747 | BS1: =EOMONTH(BQ1,1) -> 45777 | BT1: =BS1 -> 45777 | BU1: =EOMONTH(BS1,1) -> 45808 | BV1: =BU1 -> 45808 | BW1: =EOMONTH(BU1,1) -> 45838 | BX1: =BW1 -> 45838 | BY1: =EOMONTH(BW1,1) -> 45869 | BZ1: =BY1 -> 45869 | CA1: =EOMONTH(BY1,1) -> 45900 | CB1: =CA1 -> 45900 | CC1: =EOMONTH(CA1,1) -> 45930 | CD1: =CC1 -> 45930 | CE1: =EOMONTH(CC1,1) -> 45961 | CF1: =CE1 -> 45961 | CG1: =EOMONTH(CE1,1) -> 45991 | CH1: =CG1 -> 45991 | CI1: =EOMONTH(CG1,1) -> 46022 | CJ1: =CI1 -> 46022 | CK1: =EOMONTH(CI1,1) -> 46053 | CL1: =CK1 -> 46053 | CM1: =EOMONTH(CK1,1) -> 46081 | CN1: =EOMONTH(CM1,1) -> 46112
F2: Actual | G2: Actual | H2: Actual | I2: Actual | J2: Actual | K2: Actual | L2: Actual | M2: Actual | N2: Actual | O2: Actual | P2: Actual | Q2: Actual | R2: Actual | S2: Actual | T2: Actual | U2: Actual | V2: Actual | W2: Plan | X2: Actual | Y2: Plan | Z2: Actual | AA2: Plan | AB2: Actual | AC2: Plan | AD2: Actual | AE2: Plan | AF2: Actual | AG2: Plan | AH2: Actual | AI2: Plan | AJ2: Actual | AK2: Plan | AL2: Actual | AM2: Plan | AN2: Actual | AO2: Plan | AP2: Actual | AQ2: Plan | AR2: Actual | AS2: Plan | AT2: Actual | AU2: Plan | AV2: Actual | AW2: Plan | AX2: Actual | AY2: Plan | AZ2: Actual | BA2: Plan | BB2: Actual | BC2: Plan | BD2: Actual | BE2: Plan | BF2: Actual | BG2: Plan | BH2: Actual | BI2: Plan | BJ2: Actual | BK2: Plan | BL2: Actual | BM2: Plan | BN2: Actual | BO2: Plan | BP2: Actual | BQ2: Plan | BR2: Actual | BS2: Plan | BT2: Actual | BU2: Plan | BV2: Actual | BW2: Plan | BX2: Actual | BY2: Plan | BZ2: Actual | CA2: Plan | CB2: Actual | CC2: Plan | CD2: Actual | CE2: Plan | CF2: Actual | CG2: Plan | CH2: Actual | CI2: Plan | CJ2: Actual | CK2: Plan | CL2: Actual | CM2: Plan | CN2: Plan
B3: =X3+Z3+AB3+AD3+AF3+AH3+AJ3+AL3+AN3+AP3+AR3+AT3 -> 3771270 | D3: =SUM(F3:V3)+X3+Z3+AB3+AD3+AF3+AH3+AJ3+AL3+AN3+AP3+AR3+AT3+AV3+AX3+AZ3+BB3+BD3+BF3+BH3+BJ3+BL3+BN3 -> 10827577 | E3: Revenue | F3: =F5+F10 -> 2173 | G3: =G5+G10 -> 3756 | H3: =H5+H10 -> 6626 | I3: =I5+I10 -> 8675 | J3: =J5+J10 -> 10229 | K3: =K5+K10 -> 15888 | L3: =L5+L10 -> 20370 | M3: =M5+M10 -> 23751 | ... CN3: =CN5+CN10 -> 1569483.2
CJ4: =CJ5*12 -> 16487484 | CL4: =CL5*12 -> 17061168
A5: =AV5+AX5+AZ5+BB5+BD5+BF5 -> 3400255 | B5: =SUM(F5:V5)+X5+AP5+AN5+AL5+AJ5+AH5+AF5+AD5+AB5+Z5+AR5+AT5 -> 4411856 | D5: =SUM(F5:V5)+X5+Z5+AB5+AD5+AF5+AH5+AJ5+AL5+AN5+AP5+AR5+AT5+AV5+AX5+AZ5+BB5+BD5+BF5+BH5+BJ5+BL5+BN5 -> 10701959 | E5: Subscription Revenue | F5: =F7+F8 -> 2173 | G5: =G7+G8 -> 3756 | H5: =H7+H8 -> 6626 | I5: =I7+I8 -> 8675 | J5: =J7+J8 -> 10229 | K5: =K7+K8 -> 15888 | L5: =L7+L8 -> 20370 | M5: =M7+M8 -> 23751 | ... CN5: =CN7+CN8 -> 1569483.2
CF6: =CF5*12 -> 15098208 | CJ6: =CJ8*12 -> 9642540 | CL6: =CL7*12 -> 7074120
B7: =SUM(F7:V7)+X7+AP7+AN7+AL7+AJ7+AH7+AF7+AD7+AB7+Z7+AR7+AT7+AV7+AX7+AZ7+BB7+BD7+BF7 -> 4771921 | D7: =SUM(F7:V7)+X7+Z7+AB7+AD7+AF7+AH7+AJ7+AL7+AN7+AP7+AR7+AT7+AV7+AX7+AZ7+BB7+BD7+BF7+BH7+BJ7+BL7+BN7 -> 6210949 | E7: India/APAC | F7: 1506 | G7: 3089 | H7: 5542 | I7: 7591 | J7: 9145 | K7: 14804 | L7: 18536 | M7: 21417 | N7: 23810 | O7: 29498 | P7: 39142 | Q7: 47563 | R7: 51871 | S7: 58109 | T7: 70577 | U7: 83178 | V7: 102303 | W7: 42312.972 | X7: 113400 | Y7: 55179.93 | Z7: 131106 | AA7: 68550.789 | AB7: 145203 | AC7: 81501.171 | AD7: 160126 | AE7: 96638.168 | AF7: 181367 | AG7: 114702.16 | AH7: 191676 | AI7: 133391.12 | AJ7: 202269 | AK7: 155107.82 | AL7: 215514 | AM7: 179593.5 | AN7: 234003 | AO7: 171509.48 | AP7: 245191 | AQ7: 184595.53 | AR7: 253609 | AS7: 203621.85 | AT7: 264946 | AU7: 220880.76 | AV7: 277680 | AW7: 239048.95 | AX7: 291420 | AY7: 255749.47 | AZ7: 305242 | BA7: 282394.29 | BB7: 317242 | BC7: 313673.77 | BD7: 320934 | BE7: 343427.5 | BF7: 333312 | BG7: 375332.71 | BH7: 337979 | BI7: 408184.09 | BJ7: 351369 | BK7: 445075.82 | BL7: 371136 | BM7: 419681.58 | BN7: 378544 | BO7: 444310.11 | BP7: 391807 | BQ7: 471175.8 | BR7: 411051 | BS7: 499633.07 | BT7: 423123 | BU7: 527578.17 | BV7: 440887 | BW7: 557698.78 | BX7: 463987 | BY7: 589894.62 | BZ7: 481220 | CA7: 624858.62 | CB7: 496125 | CC7: 663420.05 | CD7: 521879 | CE7: 700950.32 | CF7: 540683 | CG7: 741349.47 | CH7: 562524 | CI7: 784396.78 | CJ7: 570412 | CK7: 830229.76 | CL7: 589510 | CM7: 879697.89 | CN7: 934057.69
B8: =X8+Z8+AB8+AD8+AF8+AH8+AJ8+AL8+AN8+AP8+AR8+AT8 -> 1385628 | D8: =SUM(F8:V8)+X8+Z8+AB8+AD8+AF8+AH8+AJ8+AL8+AN8+AP8+AR8+AT8+AV8+AX8+AZ8+BB8+BD8+BF8+BH8+BJ8+BL8+BN8 -> 4491010 | E8: NA/EU | F8: 667 | G8: 667 | H8: 1084 | I8: 1084 | J8: 1084 | K8: 1084 | L8: 1834 | M8: 2334 | N8: 2334 | O8: 2959 | P8: 4597 | Q8: 5430 | R8: 6985 | S8: 11260 | T8: 12895 | U8: 15687 | V8: 28152 | W8: 152593.67 | X8: 37069 | Y8: 169625.69 | Z8: 47231 | AA8: 187848.51 | AB8: 67755 | AC8: 206076.29 | AD8: 78460 | AE8: 223972.83 | AF8: 90826 | AG8: 243649.37 | AH8: 106550 | AI8: 263838.8 | AJ8: 126968 | AK8: 283983.21 | AL8: 139617 | AM8: 304671.4 | AN8: 154172 | AO8: 276965.31 | AP8: 166473 | AQ8: 283518.43 | AR8: 177149 | AS8: 290098.19 | AT8: 193358 | AU8: 298794.65 | AV8: 206593 | AW8: 308544.62 | AX8: 229938 | AY8: 319037.53 | AZ8: 255393 | BA8: 332886.32 | BB8: 274088 | BC8: 349636.57 | BD8: 282492 | BE8: 367518.74 | BF8: 305921 | BG8: 386783.82 | BH8: 325896 | BI8: 406636.85 | BJ8: 349693 | BK8: 426848.16 | BL8: 374065 | BM8: 424579.62 | BN8: 401166 | BO8: 441822.57 | BP8: 443202 | BQ8: 459368.77 | BR8: 476325 | BS8: 477969.49 | BT8: 498445 | BU8: 496011.46 | BV8: 517737 | BW8: 509744.49 | BX8: 567204 | BY8: 523411 | BZ8: 598856 | CA8: 536673.3 | CB8: 640206 | CC8: 550277.48 | CD8: 677024 | CE8: 563164.91 | CF8: 717501 | CG8: 576870.96 | CH8: 756733 | CI8: 590968.53 | CJ8: 803545 | CK8: 605533.4 | CL8: 832254 | CM8: 620500.89 | CN8: 635425.51
CJ9: =CJ7*12 -> 6844944 | CL9: =CL8*12 -> 9987048
B10: =SUM(F10:V10)+X10+AP10+AN10+AL10+AJ10+AH10+AF10+AD10+AB10+Z10+AR10+AT10+AV10+AX10+AZ10+BB10+BD10+BF10 -> 94270 | D10: =SUM(F10:V10)+X10+Z10+AB10+AD10+AF10+AH10+AJ10+AL10+AN10+AP10+AR10+AT10+AV10+AX10+AZ10+BB10+BD10+BF10+BH10+BJ10+BL10+BN10 -> 125618 | E10: Non-Recurring Revenue | F10: 0 | G10: 0 | H10: 0 | I10: 0 | J10: 0 | K10: 0 | L10: 0 | M10: 0 | N10: 158 | O10: 223 | P10: 293 | Q10: 600 | R10: 908 | S10: 1102 | T10: 1220 | U10: 1220 | V10: 1697 | X10: 3034 | Z10: 3088 | AB10: 3439 | AD10: 3375 | AF10: 3433 | AH10: 3549 | AJ10: 3937 | AL10: 3661 | AN10: 4233 | AP10: 4695 | AR10: 4828 | AT10: 5960 | AV10: 5252 | AX10: 6382 | AZ10: 6332 | BB10: 6906 | BD10: 7078 | BF10: 7667 | BH10: 7368 | BJ10: 8170 | BL10: 7904 | BN10: 7906 | BP10: 9123 | BR10: 8249 | BT10: 8505 | BV10: 7980 | BX10: 8407 | BZ10: 8357 | CB10: 8722 | CD10: 9169 | CF10: 9564 | CH10: 9633 | CJ10: 10150 | CL10: 11208
E12: Cost of Goods Sold (COGS) | F12: =SUM(F14:F15) -> 649.0122 | G12: =SUM(G14:G15) -> 375 | H12: =SUM(H14:H15) -> 1348 | I12: =SUM(I14:I15) -> 1864 | J12: =SUM(J14:J15) -> 2245 | K12: =SUM(K14:K15) -> 3392.5488 | L12: =SUM(L14:L15) -> 5215.2805 | M12: =SUM(M14:M15) -> 5090.9878 | ... CN12: =SUM(CN14:CN15) -> 271448.45
W13: 0.6 | Y13: 0.6 | AA13: 0.6 | AC13: 0.6 | AE13: 0.6 | AG13: 0.6 | AI13: 0.6 | AK13: 0.6 | AM13: 0.6 | AO13: 0.6 | AQ13: 0.6 | AS13: 0.6 | AU13: 0.6 | AW13: 0.6 | AY13: 0.6 | BA13: 0.6 | BC13: 0.6 | BE13: 0.6 | BG13: 0.6 | BI13: 0.6 | BK13: 0.6 | BM13: 0.6 | BO13: 0.6 | BQ13: 0.6 | BS13: 0.6 | BU13: 0.6 | BW13: 0.6 | BY13: 0.6 | CA13: 0.6 | CC13: 0.6 | CE13: 0.6 | CG13: 0.6 | CI13: 0.6 | CK13: 0.6 | CM13: 0.6 | CN13: 0.6
A14: =$E$12&E14 -> Cost of Goods Sold (COGS)Server Hosting charges - Direct expenses | E14: Server Hosting charges - Direct expenses | F14: 649.0122 | G14: 0 | H14: 0 | I14: 0 | J14: 0 | K14: 77.54878 | L14: 927.28049 | M14: 187.9878 | N14: 0 | O14: 0 | P14: 69.048057 | Q14: 70.929103 | R14: 0 | S14: 0 | T14: 3.5308537 | U14: 377.33764 | V14: 0 | W14: 5629 | X14: 70.856098 | Y14: 6396 | Z14: 233.03195 | AA14: 7178 | AB14: 71.049756 | AC14: 7929 | AD14: 71.221951 | AE14: 8696 | AF14: 2885.5999 | AG14: 9494 | AH14: 2393.3604 | AI14: 10291 | AJ14: 10067.012 | AK14: 11104 | AL14: 13594.867 | AM14: 11933 | AN14: 14779.524 | AO14: 20000 | AP14: 13933.258 | AQ14: 21000 | AR14: 14861.563 | AS14: 22050 | AT14: 16545.515 | AU14: 23152.5 | AV14: 16194.994 | AW14: 24310.125 | AX14: 21332.801 | AY14: 25525.631 | AZ14: 22090.418 | BA14: 26801.913 | BB14: 25852.186 | BC14: 28142.008 | BD14: 26012.77 | BE14: 29549.109 | BF14: 29337.19 | BG14: 31026.564 | BH14: 31880.434 | BI14: 32577.893 | BJ14: 32982.835 | BK14: 34206.787 | BL14: 33589.732 | BM14: 35917.127 | BN14: 35202.978 | BO14: 37712.983 | BP14: 35202.978 | BQ14: 41484.281 | BR14: 35202.978 | BS14: 45632.709 | BT14: 43998.504 | BU14: 50195.98 | BV14: 43457.636 | BW14: 55215.578 | BX14: 49491.65 | BY14: 60737.136 | BZ14: 47989.219 | CA14: 66810.85 | CB14: 53346.931 | CC14: 73491.935 | CD14: 58932.474 | CE14: 80841.128 | CF14: 53610.119 | CG14: 88925.241 | CH14: 53267.091 | CI14: 97817.765 | CJ14: 58503.515 | CK14: 107599.54 | CL14: 61913.64 | CM14: 118359.5 | CN14: 130195.45
A15: =$E$12&E15 -> Cost of Goods Sold (COGS)Direct Expenses for third-party Audit | B15: =X15+Z15+AB15+AD15+AF15+AH15+AJ15+AL15+AN15+AP15+AR15+AT15+SUM(F15:U15) -> 687310 | E15: Direct Expenses for third-party Audit | F15: 0 | G15: 375 | H15: 1348 | I15: 1864 | J15: 2245 | K15: 3315 | L15: 4288 | M15: 4903 | N15: 5620 | O15: 7509 | P15: 9586 | Q15: 11476 | R15: 12889 | S15: 14764 | T15: 16805 | U15: 19317 | V15: 24573 | W15: 33533.333 | X15: 28534 | Y15: 37750 | Z15: 33172 | AA15: 42146.667 | AB15: 37685 | AC15: 46225 | AD15: 40781 | AE15: 50391.667 | AF15: 45095 | AG15: 54771.667 | AH15: 49629 | AI15: 59271.667 | AJ15: 49807 | AK15: 63430 | AL15: 52160 | AM15: 67538.333 | AN15: 56181 | AO15: 50000 | AP15: 57766 | AQ15: 44170.525 | AR15: 59267 | AS15: 37707.213 | AT15: 60929 | AU15: 43018.223 | AV15: 60756 | AW15: 37375.725 | AX15: 61996 | AY15: 36851.969 | AZ15: 63280 | BA15: 39158.534 | BB15: 63281 | BC15: 58310.806 | BD15: 62681 | BE15: 69162.82 | BF15: 63337 | BG15: 68595.692 | BH15: 63850 | BI15: 73685.221 | BJ15: 65641 | BK15: 75894.35 | BL15: 67426 | BM15: 84426 | BN15: 67942 | BO15: 88613 | BP15: 71325 | BQ15: 93054 | BR15: 74298 | BS15: 97760 | BT15: 74382 | BU15: 102359 | BV15: 73058 | BW15: 106744 | BX15: 77284 | BY15: 105764 | BZ15: 80568 | CA15: 110346 | CB15: 78588 | CC15: 115301 | CD15: 79967 | CE15: 120091 | CF15: 80952 | CG15: 118640 | CH15: 82470 | CI15: 123783 | CJ15: 83191 | CK15: 129219 | CL15: 85159 | CM15: 135018 | CN15: 141253
E17: Customer Success | F17: =SUM(F18:F20) -> 0 | G17: =SUM(G18:G20) -> 0 | H17: =SUM(H18:H20) -> 0 | I17: =SUM(I18:I20) -> 80.378049 | J17: =SUM(J18:J20) -> 1941.8462 | K17: =SUM(K18:K20) -> 4839.1171 | L17: =SUM(L18:L20) -> 6040.9012 | M17: =SUM(M18:M20) -> 6573.4774 | ... CN17: =SUM(CN18:CN20) -> 75379.498
A18: =$E$17&E18 -> Customer SuccessPeople cost | E18: People cost | F18: 0 | G18: 0 | H18: 0 | I18: 80.378049 | J18: 1811.5657 | K18: 4408.5439 | L18: 5494.7122 | M18: 5518.3098 | N18: 12565.105 | O18: 7347.578 | P18: 9429.4046 | Q18: 15857.144 | R18: 7281.5927 | S18: 8079.2488 | T18: 16948.288 | U18: 15504.585 | V18: 16942.427 | W18: 26054.878 | X18: 19138.476 | Y18: 28213.415 | Z18: 22591.854 | AA18: 27774.39 | AB18: 22756.432 | AC18: 28213.415 | AD18: 24854.164 | AE18: 28213.415 | AF18: 21100.62 | AG18: 34207.317 | AH18: 22127.457 | AI18: 34207.317 | AJ18: 24891.362 | AK18: 34207.317 | AL18: 24942.857 | AM18: 42615.854 | AN18: 29502.437 | AO18: 17405.866 | AP18: 31508.956 | AQ18: 17607.944 | AR18: 26173.211 | AS18: 31572.897 | AT18: 28861.034 | AU18: 34425.19 | AV18: 36691.331 | AW18: 49420.688 | AX18: 35241.281 | AY18: 49660.504 | AZ18: 27378.524 | BA18: 52330.54 | BB18: 31099.617 | BC18: 52983.182 | BD18: 32805.338 | BE18: 61455.029 | BF18: 33158.388 | BG18: 53857.742 | BH18: 37263.781 | BI18: 55376.004 | BJ18: 39643.067 | BK18: 56979.091 | BL18: 40054.288 | BM18: 40490.453 | BN18: 44544.271 | BO18: 41990.453 | BP18: 43095.588 | BQ18: 42890.453 | BR18: 43571.642 | BS18: 44390.453 | BT18: 55503.874 | BU18: 45290.453 | BV18: 63789.899 | BW18: 46534.498 | BX18: 67453.103 | BY18: 60019.498 | BZ18: 71392.147 | CA18: 60019.498 | CB18: 71485.056 | CC18: 63559.498 | CD18: 66824.746 | CE18: 62659.498 | CF18: 67964.129 | CG18: 67699.498 | CH18: 69770.346 | CI18: 66199.498 | CJ18: 72648.867 | CK18: 70339.498 | CL18: 71151.117 | CM18: 71989.498 | CN18: 73879.498
A19: =$E$17&E19 -> Customer SuccessTravel and expenses | E19: Travel and expenses | F19: 0 | G19: 0 | H19: 0 | I19: 0 | J19: 130.28049 | K19: 248.93902 | L19: 346.55488 | M19: 341.28049 | N19: 0 | O19: 321.26024 | P19: 16.231707 | Q19: 417.58537 | R19: 1088.0838 | S19: 0 | T19: 348.96415 | U19: 24.317073 | V19: 317.95744 | W19: 0 | X19: 0 | Y19: 0 | Z19: 35.426829 | AA19: 0 | AB19: 0 | AC19: 0 | AD19: 21.853659 | AE19: 0 | AF19: 83.378049 | AG19: 0 | AH19: 0 | AI19: 0 | AJ19: 115.85366 | AK19: 0 | AL19: 0 | AM19: 0 | AN19: 1777.0637 | AO19: 0 | AP19: 0 | AQ19: 0 | AR19: 180.72289 | AS19: 0 | AT19: 51.771084 | AU19: 0 | AV19: 440.79548 | AW19: 0 | AX19: 1059.9735 | AY19: 0 | AZ19: 927.26512 | BA19: 0 | BB19: 293.88095 | BC19: 0 | BD19: 1329.8089 | BE19: 0 | BF19: 373.30429 | BG19: 0 | BH19: 879.12048 | BI19: 0 | BJ19: 579.65333 | BK19: 0 | BL19: 992.84929 | BM19: 0 | BN19: 2146.57 | BO19: 0 | BP19: 1191.7598 | BQ19: 0 | BR19: 4344.3087 | BS19: 0 | BT19: 2630.7406 | BU19: 0 | BV19: 0 | BW19: 0 | BX19: 891.50906 | BY19: 0 | BZ19: 808.96365 | CA19: 0 | CB19: 929.29635 | CC19: 0 | CD19: 1807.7594 | CE19: 0 | CF19: 202.32941 | CG19: 0 | CH19: 484.336 | CI19: 0 | CJ19: 493.76141 | CK19: 0 | CL19: 0 | CM19: 0 | CN19: 0
A20: =$E$17&E20 -> Customer SuccessSoftware subscription | E20: Software subscription | F20: 0 | G20: 0 | H20: 0 | I20: 0 | J20: 0 | K20: 181.63415 | L20: 199.63415 | M20: 713.8872 | N20: 713.8872 | O20: 713.8872 | P20: 1729.8872 | Q20: 1729.7848 | R20: 2448.924 | S20: 2317.4439 | T20: 3217.6024 | U20: 2317.4439 | V20: 2399.4289 | W20: 2511 | X20: 2566.8382 | Y20: 2547 | Z20: 2389.8748 | AA20: 2547 | AB20: 1875.6217 | AC20: 3003 | AD20: 1875.6217 | AE20: 3003 | AF20: 1875.6217 | AG20: 3003 | AH20: 875.62172 | AI20: 3213 | AJ20: 841.72412 | AK20: 3423 | AL20: 372.06504 | AM20: 3423 | AN20: 758.06504 | AO20: 1500 | AP20: 755.00402 | AQ20: 1500 | AR20: 755.00402 | AS20: 1500 | AT20: 755.00402 | AU20: 1500 | AV20: 503.75 | AW20: 1500 | AX20: 503.75 | AY20: 1500 | AZ20: 503.75 | BA20: 1500 | BB20: 1810.56 | BC20: 1500 | BD20: 1810.56 | BE20: 1500 | BF20: 1810.56 | BG20: 1500 | BH20: 1810.56 | BI20: 1500 | BJ20: 1693.02 | BK20: 1500 | BL20: 1306.81 | BM20: 1500 | BN20: 1306.81 | BO20: 1500 | BP20: 1306.81 | BQ20: 1500 | BR20: 1306.81 | BS20: 1500 | BT20: 1340.4608 | BU20: 1500 | BV20: 1327.7989 | BW20: 1500 | BX20: 1695.33 | BY20: 1500 | BZ20: 1638.52 | CA20: 1500 | CB20: 2971.85 | CC20: 1500 | CD20: 2971.85 | CE20: 1500 | CF20: 2959.6265 | CG20: 1500 | CH20: 4913.81 | CI20: 1500 | CJ20: 3525.46 | CK20: 1500 | CL20: 2971.85 | CM20: 1500 | CN20: 1500
E22: Total COGS | F22: =SUM(F12,F17) -> 649.0122 | G22: =SUM(G12,G17) -> 375 | H22: =SUM(H12,H17) -> 1348 | I22: =SUM(I12,I17) -> 1944.378 | J22: =SUM(J12,J17) -> 4186.8462 | K22: =SUM(K12,K17) -> 8231.6659 | L22: =SUM(L12,L17) -> 11256.182 | M22: =SUM(M12,M17) -> 11664.465 | ... CN22: =SUM(CN12,CN17) -> 346827.94
E24: Gross profit | F24: =F3-SUM(F14:F15)-SUM(F18:F20) -> 1523.9878 | G24: =G3-SUM(G14:G15)-SUM(G18:G20) -> 3381 | H24: =H3-SUM(H14:H15)-SUM(H18:H20) -> 5278 | I24: =I3-SUM(I14:I15)-SUM(I18:I20) -> 6730.622 | J24: =J3-SUM(J14:J15)-SUM(J18:J20) -> 6042.1538 | K24: =K3-SUM(K14:K15)-SUM(K18:K20) -> 7656.3341 | L24: =L3-SUM(L14:L15)-SUM(L18:L20) -> 9113.8183 | M24: =M3-SUM(M14:M15)-SUM(M18:M20) -> 12086.535 | ... CN24: =CN3-SUM(CN14:CN15)-SUM(CN18:CN20) -> 1222655.3
E25: Gross Margin (%) | F25: =F24/F3 -> 0.70132895 | G25: =G24/G3 -> 0.90015974 | H25: =H24/H3 -> 0.79655901 | I25: =I24/I3 -> 0.7758642 | J25: =J24/J3 -> 0.59068861 | K25: =+K24/K3 -> 0.48189414 | L25: =+L24/L3 -> 0.44741376 | M25: =+M24/M3 -> 0.5088853 | N25: =N24/N3 -> 0.28146179 | O25: =O24/O3 -> 0.51371709 | P25: =P24/P3 -> 0.52692198 | Q25: =Q24/Q3 -> 0.44859509 | R25: =R24/R3 -> 0.60331302 | S25: =S24/S3 -> 0.64296388 | T25: =T24/T3 -> 0.55930448 | U25: =U24/U3 -> 0.62491199 | ... CN25: =CN24/CN3 -> 0.77901774
A27: =E27&E27 -> Other IncomeOther Income | E27: Other Income | F27: 0 | G27: 0 | H27: 0 | I27: 0 | J27: 0 | K27: 0 | L27: 0 | M27: 0 | N27: 0 | O27: 0 | W27: 0 | Y27: 0 | AA27: 0 | AC27: 0 | AE27: 0 | AG27: 0 | AI27: 0 | AK27: 0 | AM27: 0 | AO27: 0 | AQ27: 0 | AS27: 0 | AU27: 0 | AW27: 0 | AY27: 0 | BA27: 0 | BC27: 0 | BE27: 0 | BG27: 0 | BI27: 0 | BK27: 0 | BM27: 0 | BO27: 0 | BQ27: 0 | BS27: 0 | BU27: 0 | BW27: 0 | BY27: 0 | CA27: 0 | CC27: 0 | CE27: 0 | CG27: 0 | CI27: 0 | CK27: 0 | CM27: 0 | CN27: 0
E28: Less: Cost
E29: Sales and Marketing Costs | F29: =SUM(F30:F37) -> 215.67634 | G29: =SUM(G30:G37) -> 513.97744 | H29: =SUM(H30:H37) -> 3818.9423 | I29: =SUM(I30:I37) -> 1240.0004 | J29: =SUM(J30:J37) -> 12171.891 | K29: =SUM(K30:K37) -> 15259.626 | L29: =SUM(L30:L37) -> 22311.458 | M29: =SUM(M30:M37) -> 32442.607 | ... AN29: =SUM(AN30:AN37) -> 305621.07 | AO29: =SUM(AO30:AO38) -> 488889.92 | AP29: =SUM(AP30:AP38) -> 410081.68 | AQ29: =SUM(AQ30:AQ38) -> 490739.59 | AR29: =SUM(AR30:AR38) -> 434726.51 | AS29: =SUM(AS30:AS38) -> 513824.82 | AT29: =SUM(AT30:AT38) -> 454074.99 | AU29: =SUM(AU30:AU38) -> 521269.27 | AV29: =SUM(AV30:AV38) -> 491256.13 | ... CN29: =SUM(CN30:CN38) -> 883744.92
A30: =$E$29&E30 -> Sales and Marketing CostsPeople cost | E30: People cost | F30: 121.95122 | G30: 0 | H30: 0 | I30: 609.34146 | J30: 2987.3678 | K30: 9462.4049 | L30: 9981.8174 | M30: 15489.498 | N30: 27217.872 | O30: 17267.461 | P30: 22233.108 | Q30: 47076.007 | R30: 32462.96 | S30: 55344.064 | T30: 98013.455 | U30: 124771.76 | V30: 150036.63 | W30: 185326 | X30: 190508.87 | Y30: 185538 | Z30: 195476.53 | AA30: 192048 | AB30: 172968.82 | AC30: 187367 | AD30: 191208.82 | AE30: 195370 | AF30: 177873.5 | AG30: 198714 | AH30: 184108.31 | AI30: 210528 | AJ30: 176158.7 | AK30: 209995 | AL30: 190077.19 | AM30: 223763 | AN30: 202423.04 | AO30: 211168.25 | AP30: 220160.56 | AQ30: 217418.25 | AR30: 219630.87 | AS30: 236168.25 | AT30: 216705.89 | AU30: 278039.33 | AV30: 266256.47 | AW30: 278039.33 | AX30: 260064.43 | AY30: 279351.83 | AZ30: 242793.61 | BA30: 266638.33 | BB30: 293937.09 | BC30: 274006.59 | BD30: 231369.95 | BE30: 292756.59 | BF30: 252301.71 | BG30: 307083.17 | BH30: 276056.97 | BI30: 307083.17 | BJ30: 267971.98 | BK30: 307083.17 | BL30: 338969.45 | BM30: 320245.91 | BN30: 315548.14 | BO30: 323192.58 | BP30: 320184.46 | BQ30: 311359.25 | BR30: 286909.55 | BS30: 324497.59 | BT30: 341285.99 | BU30: 310072.59 | BV30: 340828.98 | BW30: 326709.59 | BX30: 395297.83 | BY30: 339694.51 | BZ30: 311095.88 | CA30: 334397.09 | CB30: 329903.88 | CC30: 332060.5 | CD30: 344346.56 | CE30: 357400.58 | CF30: 379463.71 | CG30: 374732.25 | CH30: 376599.69 | CI30: 416963.08 | CJ30: 386587.34 | CK30: 402394.67 | CL30: 389680.68 | CM30: 384592.69 | CN30: 393759.35
A31: =$E$29&E31 -> Sales and Marketing CostsTravel and expenses | E31: Travel and expenses | F31: 0 | G31: 0 | H31: 0 | I31: 0 | J31: 0 | K31: 103.26829 | L31: 783.28049 | M31: 296.29268 | N31: 1886.5884 | O31: 1373.6818 | P31: 2993.9756 | Q31: 1225.8415 | R31: 6800.0809 | S31: 13191.976 | T31: 1981.8482 | U31: 12469.123 | V31: 5031.3894 | W31: 24097.561 | X31: 7056.6017 | Y31: 24097.561 | Z31: 14606.364 | AA31: 24097.561 | AB31: 5933.3143 | AC31: 23275.61 | AD31: 24531.59 | AE31: 23275.61 | AF31: 20689.305 | AG31: 23275.61 | AH31: 41496.658 | AI31: 23653.659 | AJ31: 29052.203 | AK31: 23653.659 | AL31: 20648.609 | AM31: 24409.756 | AN31: 8405.2498 | AO31: 26675 | AP31: 15032.623 | AQ31: 28341.667 | AR31: 23843.306 | AS31: 28445.833 | AT31: 22492.2 | AU31: 29383.333 | AV31: 44783.074 | AW31: 29383.333 | AX31: 22355.383 | AY31: 29383.333 | AZ31: 5171.2168 | BA31: 29591.667 | BB31: 14462.177 | BC31: 29800 | BD31: 11193.15 | BE31: 30633.333 | BF31: 3881.2852 | BG31: 31050 | BH31: 22174.092 | BI31: 31050 | BJ31: 10667.803 | BK31: 31050 | BL31: 15191.272 | BM31: 12479.167 | BN31: 5105.5321 | BO31: 12479.167 | BP31: 1223.0979 | BQ31: 12479.167 | BR31: 9422.4119 | BS31: 12479.167 | BT31: 10923.405 | BU31: 12479.167 | BV31: 19717.548 | BW31: 12062.5 | BX31: 11143.985 | BY31: 12479.167 | BZ31: 2909.9082 | CA31: 12062.5 | CB31: 2788.23 | CC31: 12062.5 | CD31: 19087.38 | CE31: 12479.167 | CF31: 14276.253 | CG31: 12479.167 | CH31: 1631.8598 | CI31: 12479.167 | CJ31: 7363.2701 | CK31: 12479.167 | CL31: 20417.681 | CM31: 12479.167 | CN31: 12479.167
A32: =$E$29&E32 -> Sales and Marketing CostsDemand Gen | E32: Demand Gen | F32: 24.365854 | G32: 365.85366 | H32: 205.08537 | I32: 404.87841 | J32: 6519.061 | K32: 4548.7927 | L32: 7638.7667 | M32: 5280.5 | N32: 3940.3576 | O32: 5303.1707 | P32: 9079.1629 | Q32: 12691.733 | R32: 18908.637 | S32: 20575.841 | T32: 14591.844 | U32: 11843.529 | V32: 32730.908 | W32: 113572 | X32: 19031.307 | Y32: 117210 | Z32: 66417.076 | AA32: 124143 | AB32: 42851.508 | AC32: 132309 | AD32: 39497.355 | AE32: 141354 | AF32: 58775.596 | AG32: 145773 | AH32: 48956.375 | AI32: 145591 | AJ32: 52157.081 | AK32: 145410 | AL32: 66542.676 | AM32: 144702 | AN32: 52985.611 | AO32: 132733.33 | AP32: 118497.86 | AQ32: 125538.33 | AR32: 125713.71 | AS32: 129802.78 | AT32: 125749.28 | AU32: 107853.95 | AV32: 106301.94 | AW32: 118863.15 | AX32: 132156.59 | AY32: 122053.64 | AZ32: 111895.94 | BA32: 124171.27 | BB32: 134984.71 | BC32: 152685.32 | BD32: 214443.18 | BE32: 187557.71 | BF32: 175400.46 | BG32: 209649.87 | BH32: 277428.81 | BI32: 213182.74 | BJ32: 249307.6 | BK32: 224745.88 | BL32: 195105.12 | BM32: 248760.94 | BN32: 243153.34 | BO32: 257327.06 | BP32: 297327.48 | BQ32: 266292.16 | BR32: 275907.03 | BS32: 250741.43 | BT32: 254066.7 | BU32: 257819.55 | BV32: 271400.6 | BW32: 265251.53 | BX32: 296909.76 | BY32: 272546.05 | BZ32: 309836.89 | CA32: 276847.15 | CB32: 267119.88 | CC32: 280257.92 | CD32: 410063.55 | CE32: 283794.51 | CF32: 425524.58 | CG32: 286319.26 | CH32: 278581.68 | CI32: 288524.52 | CJ32: 288037.53 | CK32: 290768.93 | CL32: 241478.75 | CM32: 293053.75 | CN32: 294985.63
A33: =$E$29&E33 -> Sales and Marketing CostsBranding and community | E33: Branding and community | F33: 0 | G33: 0 | H33: 0 | I33: 0 | J33: 0 | K33: 0 | L33: 0 | M33: 0 | N33: 2274.7073 | O33: 2302.7195 | P33: 0 | Q33: 408.66854 | R33: 1941.0122 | S33: 2176.2601 | T33: 1707.3171 | U33: 10934.837 | V33: 2312.7347 | W33: 8100 | X33: 19481.149 | Y33: 8100 | Z33: 0 | AA33: 8100 | AB33: 0 | AC33: 20750 | AD33: 7637.0336 | AE33: 20750 | AF33: 10960.815 | AG33: 20750 | AH33: 4288.9228 | AI33: 20750 | AJ33: 4288.9228 | AK33: 20750 | AL33: 6156.8435 | AM33: 20750 | AN33: 6156.8435 | AO33: 17250 | AP33: 6082.6647 | AQ33: 17250 | AR33: 6082.6647 | AS33: 17250 | AT33: 15934.172 | AU33: 2916.6667 | AV33: 25554.308 | AW33: 2916.6667 | AX33: 13938.936 | AY33: 2916.6667 | AZ33: 27157.889 | BA33: 2916.6667 | BB33: 3879.9402 | BC33: 2916.6667 | BD33: 9544.9402 | BE33: 2916.6667 | BF33: 31773.988 | BG33: 27916.667 | BH33: 32131.387 | BI33: 27916.667 | BJ33: 20908.631 | BK33: 27916.667 | BL33: 29640.391 | BM33: 25833.333 | BN33: 19194.156 | BO33: 25833.333 | BP33: 20601.979 | BQ33: 25833.333 | BR33: 56012.236 | BS33: 29828.467 | BT33: 69206.888 | BU33: 29948.467 | BV33: 76812.743 | BW33: 30071.8 | BX33: 55728.502 | BY33: 30198.467 | BZ33: 42645.211 | CA33: 30328.467 | CB33: 20847.106 | CC33: 32961.8 | CD33: 18242.097 | CE33: 33101.8 | CF33: 11564.81 | CG33: 33101.8 | CH33: 11446.894 | CI33: 33101.8 | CJ33: 15433.45 | CK33: 34833.333 | CL33: 12705.141 | CM33: 34833.333 | CN33: 34833.333
A34: =$E$29&E34 -> Sales and Marketing CostsMarketing Tech Stack | E34: Marketing Tech Stack | F34: 55.871463 | G34: 28.400854 | H34: 2691.857 | I34: 0 | J34: 2433.0844 | K34: 763.52049 | L34: 2483.6122 | M34: 3080.0669 | N34: 1923.3144 | O34: 3820.8916 | P34: 2771.5731 | Q34: 4246.6987 | R34: 5064.429 | S34: 3388.6898 | T34: 5399.9064 | U34: 3273.3351 | V34: 2186.5751 | W34: 11921.951 | X34: 49286.417 | Y34: 11800 | Z34: 24708.869 | AA34: 26150 | AB34: 24362.622 | AC34: 11921.951 | AD34: 15163.444 | AE34: 12226.829 | AF34: 17950.254 | AG34: 12226.829 | AH34: 18396.654 | AI34: 12470.732 | AJ34: 10471.585 | AK34: 12470.732 | AL34: 9041.7052 | AM34: 12714.634 | AN34: 5898.4552 | AO34: 24330 | AP34: 11068.886 | AQ34: 24795 | AR34: 16777.536 | AS34: 25271.625 | AT34: 20731.516 | AU34: 26280.166 | AV34: 19285.986 | AW34: 26780.92 | AX34: 28884.936 | AY34: 27294.193 | AZ34: 15876.187 | BA34: 29077.909 | BB34: 16990.749 | BC34: 30073.265 | BD34: 16444.843 | BE34: 31115.78 | BF34: 24737.16 | BG34: 32207.746 | BH34: 19972.812 | BI34: 33351.569 | BJ34: 21413.902 | BK34: 34549.774 | BL34: 25919.356 | BM34: 35805.67 | BN34: 20895.669 | BO34: 37121.392 | BP34: 25107.122 | BQ34: 38499.858 | BR34: 36684.911 | BS34: 39661.334 | BT34: 37555.488 | BU34: 41043.543 | BV34: 21009.778 | BW34: 42494.862 | BX34: 21059.618 | BY34: 44018.747 | BZ34: 23934.648 | CA34: 45618.826 | CB34: 21632.738 | CC34: 47298.909 | CD34: 22646.588 | CE34: 49062.996 | CF34: 20957.328 | CG34: 50915.288 | CH34: 28042.403 | CI34: 52860.194 | CJ34: 23299.033 | CK34: 54902.346 | CL34: 23309.378 | CM34: 57046.605 | CN34: 59298.077
A35: =$E$29&E35 -> Sales and Marketing CostsContent | E35: Content | F35: 13.487805 | G35: 119.72293 | H35: 922 | I35: 225.78049 | J35: 232.37805 | K35: 381.63976 | L35: 40.176341 | M35: 4714.969 | N35: 40.176341 | O35: 11115.457 | P35: 12334.969 | Q35: 9978.8916 | R35: 4186.6924 | S35: 6757.3554 | T35: 8143.5787 | U35: 3774.7293 | V35: 9567.2796 | W35: 13395.122 | X35: 13715.524 | Y35: 13395.122 | Z35: 23324.329 | AA35: 18395.122 | AB35: 16886.256 | AC35: 13395.122 | AD35: 13370.376 | AE35: 12195.122 | AF35: 10898.915 | AG35: 21195.122 | AH35: 10940.585 | AI35: 16195.122 | AJ35: 10531.273 | AK35: 16195.122 | AL35: 10699.153 | AM35: 21195.122 | AN35: 10785.395 | AO35: 24033.333 | AP35: 10490.325 | AQ35: 24533.333 | AR35: 10731.289 | AS35: 23858.333 | AT35: 12396.108 | AU35: 24109.583 | AV35: 6475 | AW35: 24688.396 | AX35: 6475 | AY35: 25296.149 | AZ35: 6825 | BA35: 24734.29 | BB35: 6475 | BC35: 25404.338 | BD35: 13425 | BE35: 24007.888 | BF35: 0 | BG35: 24233.333 | BH35: 9767.95 | BI35: 24233.333 | BJ35: 0 | BK35: 30900 | BL35: 6733.67 | BM35: 18417.857 | BN35: 1666.67 | BO35: 18496.607 | BP35: 17021.67 | BQ35: 18579.295 | BR35: 8666.67 | BS35: 18666.117 | BT35: 1666.67 | BU35: 18757.279 | BV35: 15666.67 | BW35: 18853.001 | BX35: 8666.67 | BY35: 18953.508 | BZ35: 8676.67 | CA35: 19059.04 | CB35: 1676.67 | CC35: 19169.849 | CD35: 1691.67 | CE35: 19286.199 | CF35: 1691.67 | CG35: 19408.366 | CH35: 17691.67 | CI35: 12869.975 | CJ35: 2225 | CK35: 13004.664 | CL35: 2225 | CM35: 13146.088 | CN35: 13294.583
A36: =$E$29&E36 -> Sales and Marketing CostsReferrals and Expansion | E36: Referrals and Expansion | F36: 0 | G36: 0 | H36: 0 | I36: 0 | J36: 0 | K36: 0 | L36: 1383.8049 | M36: 3581.2805 | N36: 3828.4634 | O36: 0 | P36: 0 | Q36: 3413.4146 | R36: 0 | S36: 1189.0244 | T36: 2990.3049 | U36: 0 | V36: 2226.0732 | W36: 13062.613 | X36: 5040.6146 | Y36: 14112.69 | Z36: 10778.085 | AA36: 14927.741 | AB36: 18436.512 | AC36: 15732.972 | AD36: 3397.2439 | AE36: 16439.519 | AF36: 14923.707 | AG36: 17085.425 | AH36: 14837.317 | AI36: 17975.268 | AJ36: 16714.951 | AK36: 19850.979 | AL36: 11075.305 | AM36: 20888.562 | AN36: 6690.2439 | AO36: 14500 | AP36: 18922.528 | AQ36: 14663 | AR36: 14302.44 | AS36: 14827.99 | AT36: 12793.524 | AU36: 13811.252 | AV36: 7142.8571 | AW36: 18626.946 | AX36: 0 | AY36: 18775.066 | AZ36: 1200 | BA36: 18844.56 | BB36: 5475 | BC36: 18876.406 | BD36: 4499 | BE36: 22157.14 | BF36: 2854.6667 | BG36: 22222.112 | BH36: 8538.3333 | BI36: 23667.733 | BJ36: 5522.619 | BK36: 23734.01 | BL36: 6408.4286 | BM36: 15296.237 | BN36: 4551.4706 | BO36: 15444.223 | BP36: 11320.5 | BQ36: 16273.396 | BR36: 10351.088 | BS36: 19136.369 | BT36: 8295 | BU36: 20108.075 | BV36: 14571 | BW36: 22685.934 | BX36: 17820.75 | BY36: 23047.393 | BZ36: 9690 | CA36: 24730.738 | CB36: 14160 | CC36: 27025.238 | CD36: 23017.907 | CE36: 24830.629 | CF36: 18245.654 | CG36: 26047.09 | CH36: 15581.692 | CI36: 26584.174 | CJ36: 16716.597 | CK36: 26853.001 | CL36: 10807.689 | CM36: 27469.639 | CN36: 30094.769
