Workbook

Sheet Working
B2: Weekday | C2: Average FTU | D2: Day factor | J2: Key Metrics | K2: 45748 | L2: 45778 | M2: 45809 | N2: 45839 | O2: 45870 | P2: 45901 | Q2: 45931 | R2: 45962 | S2: =EOMONTH(R2,1) -> 46022
B3: Monday | C3: 2606.6667 | D3: =C3/C$3 -> 1 | J3: Demand
B4: Tuesday | C4: 2470 | D4: =C4/C$3 -> 0.94757033
B5: Wednesday | C5: 2567 | D5: =C5/C$3 -> 0.98478261 | J5: MTU repeat rate | K5: ='Key Metrics'!F13/'Key Metrics'!#REF! -> #REF! | L5: ='Key Metrics'!G13/'Key Metrics'!F11 -> 0.67018616 | M5: ='Key Metrics'!H13/'Key Metrics'!G11 -> 0.60309138 | N5: ='Key Metrics'!I13/'Key Metrics'!H11 -> 0.60378781 | O5: ='Key Metrics'!J13/'Key Metrics'!I11 -> 0.61962328 | P5: ='Key Metrics'!K13/'Key Metrics'!J11 -> 0.56835913 | Q5: ='Key Metrics'!L13/'Key Metrics'!K11 -> 0.60449724 | R5: 0.57 | S5: 0.6
B6: Thursday | C6: 2624 | D6: =C6/C$3 -> 1.0066496
B7: Friday | C7: 2722.6667 | D7: =C7/C$3 -> 1.0445013
B8: Saturday | C8: 3350.3333 | D8: =C8/C$3 -> 1.2852941
B9: Sunday | C9: 3772.3333 | D9: =C9/C$3 -> 1.4471867
B11: Nov'25 | F11: Dec'25 | H11: 0.2
B12: Date | C12: Weekday | D12: FTU | F12: Date | G12: Weekday | H12: FTU
B13: 45962 | C13: Saturday | D13: 2978 | F13: 45992 | G13: =TEXT(F13, "dddd") -> Monday | H13: =D15*(1+H11) -> 2688
B14: =B13+1 -> 45963 | C14: Sunday | D14: 3547 | F14: =F13+1 -> 45993 | G14: =TEXT(F14, "dddd") -> Tuesday | H14: =H13*$D4 -> 2547.0691
B15: =B14+1 -> 45964 | C15: Monday | D15: 2240 | F15: =F14+1 -> 45994 | G15: =TEXT(F15, "dddd") -> Wednesday | H15: =H14*$D5 -> 2508.3093
B16: =B15+1 -> 45965 | C16: Tuesday | D16: 2072 | F16: =F15+1 -> 45995 | G16: =TEXT(F16, "dddd") -> Thursday | H16: =H15*$D6 -> 2524.9886
B17: =B16+1 -> 45966 | C17: =TEXT(B17, "dddd") -> Wednesday | D17: =ROUND($D$15*D5,0) -> 2206 | F17: =F16+1 -> 45996 | G17: =TEXT(F17, "dddd") -> Friday | H17: =H16*$D7 -> 2637.3538
B18: =B17+1 -> 45967 | C18: =TEXT(B18, "dddd") -> Thursday | D18: =ROUND($D$15*D6,0) -> 2255 | F18: =F17+1 -> 45997 | G18: =TEXT(F18, "dddd") -> Saturday | H18: =H17*$D8 -> 3389.7754
B19: =B18+1 -> 45968 | C19: =TEXT(B19, "dddd") -> Friday | D19: =ROUND($D$15*D7,0) -> 2340 | F19: =F18+1 -> 45998 | G19: =TEXT(F19, "dddd") -> Sunday | H19: =H18*$D9 -> 4905.6378
B20: =B19+1 -> 45969 | C20: =TEXT(B20, "dddd") -> Saturday | D20: =ROUND($D$15*D8,0) -> 2879 | F20: =F19+1 -> 45999 | G20: =TEXT(F20, "dddd") -> Monday | H20: =H13 -> 2688
B21: =B20+1 -> 45970 | C21: =TEXT(B21, "dddd") -> Sunday | D21: =ROUND($D$15*D9,0) -> 3242 | F21: =F20+1 -> 46000 | G21: =TEXT(F21, "dddd") -> Tuesday | H21: =H14 -> 2547.0691
B22: =B21+1 -> 45971 | C22: =TEXT(B22, "dddd") -> Monday | D22: =D15 -> 2240 | F22: =F21+1 -> 46001 | G22: =TEXT(F22, "dddd") -> Wednesday | H22: =H15 -> 2508.3093
B23: =B22+1 -> 45972 | C23: =TEXT(B23, "dddd") -> Tuesday | D23: =D16 -> 2072 | F23: =F22+1 -> 46002 | G23: =TEXT(F23, "dddd") -> Thursday | H23: =H16 -> 2524.9886
B24: =B23+1 -> 45973 | C24: =TEXT(B24, "dddd") -> Wednesday | D24: =D17 -> 2206 | F24: =F23+1 -> 46003 | G24: =TEXT(F24, "dddd") -> Friday | H24: =H17 -> 2637.3538
B25: =B24+1 -> 45974 | C25: =TEXT(B25, "dddd") -> Thursday | D25: =D18 -> 2255 | F25: =F24+1 -> 46004 | G25: =TEXT(F25, "dddd") -> Saturday | H25: =H18 -> 3389.7754
B26: =B25+1 -> 45975 | C26: =TEXT(B26, "dddd") -> Friday | D26: =D19 -> 2340 | F26: =F25+1 -> 46005 | G26: =TEXT(F26, "dddd") -> Sunday | H26: =H19 -> 4905.6378
B27: =B26+1 -> 45976 | C27: =TEXT(B27, "dddd") -> Saturday | D27: =D20 -> 2879 | F27: =F26+1 -> 46006 | G27: =TEXT(F27, "dddd") -> Monday | H27: =H20 -> 2688
B28: =B27+1 -> 45977 | C28: =TEXT(B28, "dddd") -> Sunday | D28: =D21 -> 3242 | F28: =F27+1 -> 46007 | G28: =TEXT(F28, "dddd") -> Tuesday | H28: =H21 -> 2547.0691
B29: =B28+1 -> 45978 | C29: =TEXT(B29, "dddd") -> Monday | D29: =D22 -> 2240 | F29: =F28+1 -> 46008 | G29: =TEXT(F29, "dddd") -> Wednesday | H29: =H22 -> 2508.3093
B30: =B29+1 -> 45979 | C30: =TEXT(B30, "dddd") -> Tuesday | D30: =D23 -> 2072 | F30: =F29+1 -> 46009 | G30: =TEXT(F30, "dddd") -> Thursday | H30: =H23 -> 2524.9886
B31: =B30+1 -> 45980 | C31: =TEXT(B31, "dddd") -> Wednesday | D31: =D24 -> 2206 | F31: =F30+1 -> 46010 | G31: =TEXT(F31, "dddd") -> Friday | H31: =H24 -> 2637.3538
B32: =B31+1 -> 45981 | C32: =TEXT(B32, "dddd") -> Thursday | D32: =D25 -> 2255 | F32: =F31+1 -> 46011 | G32: =TEXT(F32, "dddd") -> Saturday | H32: =H25 -> 3389.7754
B33: =B32+1 -> 45982 | C33: =TEXT(B33, "dddd") -> Friday | D33: =D26 -> 2340 | F33: =F32+1 -> 46012 | G33: =TEXT(F33, "dddd") -> Sunday | H33: =H26 -> 4905.6378
... B42: =B41+1 -> 45991 | C42: =TEXT(B42, "dddd") -> Sunday | D42: =D35 -> 3242 | F42: =F41+1 -> 46021 | G42: =TEXT(F42, "dddd") -> Tuesday | H42: =H35 -> 2547.0691
F43: =F42+1 -> 46022 | G43: =TEXT(F43, "dddd") -> Wednesday | H43: =H36 -> 2508.3093
B44: Total | D44: =SUM(D13:D43) -> 75461 | F44: Total | H44: =SUM(H13:H43) -> 92547.914

Sheet Key Metrics
C2: Actual | D2: Actual | E2: Actual | F2: Actual | G2: Actual | H2: Actual | I2: Actual | J2: Actual | K2: Actual | L2: Actual | M2: Actual | N2: Actual
B3: Key Metrics | C3: 45688 | D3: =EOMONTH(C3,1) -> 45716 | E3: =EOMONTH(D3,1) -> 45747 | F3: =EOMONTH(E3,1) -> 45777 | G3: =EOMONTH(F3,1) -> 45808 | H3: =EOMONTH(G3,1) -> 45838 | I3: =EOMONTH(H3,1) -> 45869 | J3: =EOMONTH(I3,1) -> 45900 | K3: =EOMONTH(J3,1) -> 45930 | ... N3: =EOMONTH(M3,1) -> 46022
F4: 506.96274 | G4: 1134.738 | H4: 1549.1958
B5: Annual Run Rate Revenue (USD Thousands) | C5: ='MIS P&L'!C7*12/88 -> 229.8297 | D5: ='MIS P&L'!D7*12/88 -> 239.00447 | E5: ='MIS P&L'!E7*12/88 -> 334.77175 | F5: ='MIS P&L'!F7*12/88 -> 460.87522 | G5: ='MIS P&L'!G7*12/88 -> 1031.6038 | H5: ='MIS P&L'!H7*12/88 -> 1408.3546 | I5: ='MIS P&L'!I7*12/88 -> 2035.9653 | J5: ='MIS P&L'!J7*12/88 -> 3757.6057 | ... N5: ='MIS P&L'!N7*12/88 -> 15923.098
B7: Micro markets | C7: 1 | D7: 2 | E7: 4 | F7: 7 | G7: 8 | H7: 15 | I7: 19 | J7: 26 | K7: 38 | L7: 51 | M7: 66 | N7: 86
B9: Demand
B11: Monthly Active Users * | C11: =SUM(C12:C13) -> 2763 | D11: =SUM(D12:D13) -> 3666 | E11: =SUM(E12:E13) -> 5437 | F11: =SUM(F12:F13) -> 7198 | G11: =SUM(G12:G13) -> 14686 | H11: =SUM(H12:H13) -> 21226 | I11: =SUM(I12:I13) -> 32013 | J11: =SUM(J12:J13) -> 54733 | ... N11: =SUM(N12:N13) -> 209901
B12: First time | C12: 966 | D12: 1583 | E12: 2682 | F12: 4037 | G12: 9862 | H12: 12369 | I12: 19197 | J12: 34897 | K12: 49119 | L12: 83204 | M12: 86837 | N12: 102395
B13: Repeat | C13: 1797 | D13: 2083 | E13: 2755 | F13: 3161 | G13: 4824 | H13: 8857 | I13: 12816 | J13: 19836 | K13: 31108 | L13: 48497 | M13: 74244 | N13: 107506
B14: Jobs | C14: =SUM(C15:C16) -> 6863 | D14: =SUM(D15:D16) -> 7519 | E14: =SUM(E15:E16) -> 10642 | F14: =SUM(F15:F16) -> 14980 | G14: =SUM(G15:G16) -> 35189 | H14: =SUM(H15:H16) -> 47211 | I14: =SUM(I15:I16) -> 68196 | J14: =SUM(J15:J16) -> 118808 | ... N14: =SUM(N15:N16) -> 518345
B15: First time | C15: 1665 | D15: 2439 | E15: 4093 | F15: 7056 | G15: 22591 | H15: 26771 | I15: 39036 | J15: 71090 | K15: 97264 | L15: 185159 | M15: 184371 | N15: 223401
B16: Repeat | C16: 5198 | D16: 5080 | E16: 6549 | F16: 7924 | G16: 12598 | H16: 20440 | I16: 29160 | J16: 47718 | K16: 70738 | L16: 123509 | M16: 191264 | N16: 294944
B17: Frequency | C17: =C14/C11 -> 2.4838943 | D17: =D14/D11 -> 2.0510093 | E17: =E14/E11 -> 1.9573294 | F17: =F14/F11 -> 2.0811336 | G17: =G14/G11 -> 2.3960915 | H17: =H14/H11 -> 2.2242062 | I17: =I14/I11 -> 2.1302596 | J17: =J14/J11 -> 2.1706831 | ... N17: =N14/N11 -> 2.4694737
B18: First Time | C18: =C15/C12 -> 1.7236025 | D18: =D15/D12 -> 1.5407454 | E18: =E15/E12 -> 1.5260999 | F18: =F15/F12 -> 1.7478325 | G18: =G15/G12 -> 2.2907118 | H18: =H15/H12 -> 2.1643625 | I18: =I15/I12 -> 2.0334427 | J18: =J15/J12 -> 2.0371379 | ... N18: =N15/N12 -> 2.1817569
B19: Repeat | C19: =C16/C13 -> 2.8925988 | D19: =D16/D13 -> 2.4387902 | E19: =E16/E13 -> 2.3771325 | F19: =F16/F13 -> 2.5068016 | G19: =G16/G13 -> 2.6115257 | H19: =H16/H13 -> 2.3077792 | I19: =I16/I13 -> 2.2752809 | J19: =J16/J13 -> 2.4056261 | ... N19: =N16/N13 -> 2.743512
B20: Jobs per Day | C20: =C14/30 -> 228.76667 | D20: =D14/30 -> 250.63333 | E20: =E14/30 -> 354.73333 | F20: =F14/30 -> 499.33333 | G20: =G14/(G$3-F$3) -> 1135.129 | H20: =H14/(H$3-G$3) -> 1573.7 | I20: =I14/(I$3-H$3) -> 2199.871 | J20: =J14/(J$3-I$3) -> 3832.5161 | K20: =K14/(K$3-J$3) -> 5600.0667 | L20: =L14/(L$3-K$3) -> 9957.0323 | M20: =M14/(M$3-L$3) -> 12521.167 | N20: =N14/(N$3-M$3) -> 16720.806
B21: First time | C21: =C15/30 -> 55.5 | D21: =D15/30 -> 81.3 | E21: =E15/30 -> 136.43333 | F21: =F15/30 -> 235.2 | G21: =G15/(G$3-F$3) -> 728.74194 | H21: =H15/(H$3-G$3) -> 892.36667 | I21: =I15/(I$3-H$3) -> 1259.2258 | J21: =J15/(J$3-I$3) -> 2293.2258 | K21: =K15/(K$3-J$3) -> 3242.1333 | L21: =L15/(L$3-K$3) -> 5972.871 | M21: =M15/(M$3-L$3) -> 6145.7 | N21: =N15/(N$3-M$3) -> 7206.4839
B22: Repeat | C22: =C16/30 -> 173.26667 | D22: =D16/30 -> 169.33333 | E22: =E16/30 -> 218.3 | F22: =F16/30 -> 264.13333 | G22: =G16/(G$3-F$3) -> 406.3871 | H22: =H16/(H$3-G$3) -> 681.33333 | I22: =I16/(I$3-H$3) -> 940.64516 | J22: =J16/(J$3-I$3) -> 1539.2903 | K22: =K16/(K$3-J$3) -> 2357.9333 | L22: =L16/(L$3-K$3) -> 3984.1613 | M22: =M16/(M$3-L$3) -> 6375.4667 | N22: =N16/(N$3-M$3) -> 9514.3226
B23: Hours | C23: =SUM(C24:C25) -> 9144.75 | D23: =SUM(D24:D25) -> 9603 | E23: =SUM(E24:E25) -> 13457.25 | F23: =SUM(F24:F25) -> 18463 | G23: =SUM(G24:G25) -> 41475.5 | H23: =SUM(H24:H25) -> 54875 | I23: =SUM(I24:I25) -> 79269.5 | J23: =SUM(J24:J25) -> 145034 | ... N23: =SUM(N24:N25) -> 648259.75
B24: First time | C24: 2163.75 | D24: 2948.5 | E24: 4872 | F24: 8340.25 | G24: 25539.5 | H24: 30253.75 | I24: 44115.5 | J24: 84742.75 | K24: 113683.75 | L24: 239537.75 | M24: 226326.75 | N24: =16322415/60 -> 272040.25
B25: Repeat | C25: 6981 | D25: 6654.5 | E25: 8585.25 | F25: 10122.75 | G25: 15936 | H25: 24621.25 | I25: 35154 | J25: 60291.25 | K25: 87714.25 | L25: 166153 | M25: 240733.67 | N25: 376219.5
B26: Hours per Day | C26: =SUM(C27:C28) -> 294.99194 | D26: =SUM(D27:D28) -> 342.96429 | E26: =SUM(E27:E28) -> 434.10484 | F26: =SUM(F27:F28) -> 615.43333 | G26: =SUM(G27:G28) -> 1337.9194 | H26: =SUM(H27:H28) -> 1829.1667 | I26: =SUM(I27:I28) -> 2557.0806 | J26: =SUM(J27:J28) -> 4678.5161 | ... N26: =SUM(N27:N28) -> 20911.605
B27: First time | C27: =C24/31 -> 69.798387 | D27: =D24/(D$3-C$3) -> 105.30357 | E27: =E24/(E$3-D$3) -> 157.16129 | F27: =F24/(F$3-E$3) -> 278.00833 | G27: =G24/(G$3-F$3) -> 823.85484 | H27: =H24/(H$3-G$3) -> 1008.4583 | I27: =I24/(I$3-H$3) -> 1423.0806 | J27: =J24/(J$3-I$3) -> 2733.6371 | K27: =K24/(K$3-J$3) -> 3789.4583 | ... N27: =N24/(N$3-M$3) -> 8775.4919
B28: Repeat | C28: =C25/31 -> 225.19355 | D28: =D25/(D$3-C$3) -> 237.66071 | E28: =E25/(E$3-D$3) -> 276.94355 | F28: =F25/(F$3-E$3) -> 337.425 | G28: =G25/(G$3-F$3) -> 514.06452 | H28: =H25/(H$3-G$3) -> 820.70833 | I28: =I25/(I$3-H$3) -> 1134 | J28: =J25/(J$3-I$3) -> 1944.879 | K28: =K25/(K$3-J$3) -> 2923.8083 | ... N28: =N25/(N$3-M$3) -> 12136.113
B29: Hours per Job | C29: =C23/C14 -> 1.3324712 | D29: =D23/D14 -> 1.2771645 | E29: =E23/E14 -> 1.2645414 | F29: =F23/F14 -> 1.23251 | G29: =G23/G14 -> 1.1786496 | H29: =H23/H14 -> 1.162335 | I29: =I23/I14 -> 1.1623776 | J29: =J23/J14 -> 1.2207427 | ... N29: =N23/N14 -> 1.2506337
B30: First time | C30: =C24/C15 -> 1.2995495 | D30: =D24/D15 -> 1.2088971 | E30: =E24/E15 -> 1.1903249 | F30: =F24/F15 -> 1.1820082 | G30: =G24/G15 -> 1.1305166 | H30: =H24/H15 -> 1.1300941 | I30: =I24/I15 -> 1.1301235 | J30: =J24/J15 -> 1.1920488 | ... N30: =N24/N15 -> 1.2177217
B31: Repeat | C31: =C25/C16 -> 1.3430165 | D31: =D25/D16 -> 1.3099409 | E31: =E25/E16 -> 1.3109253 | F31: =F25/F16 -> 1.2774798 | G31: =G25/G16 -> 1.2649627 | H31: =H25/H16 -> 1.2045621 | I31: =I25/I16 -> 1.2055556 | J31: =J25/J16 -> 1.2634907 | ... N31: =N25/N16 -> 1.2755625
B33: Supply
B35: Onboarded | C35: 37 | D35: 40 | E35: 109 | F35: 245 | G35: 333 | H35: 670 | I35: 678 | J35: 1032 | K35: 1564 | L35: 2123 | M35: 2760 | N35: 3343
B36: Active Experts | C36: =SUM(C37:C38) -> 121 | D36: =SUM(D37:D38) -> 150 | E36: =SUM(E37:E38) -> 224 | F36: =SUM(F37:F38) -> 386 | G36: =SUM(G37:G38) -> 637 | H36: =SUM(H37:H38) -> 1113 | I36: =SUM(I37:I38) -> 1566 | J36: =SUM(J37:J38) -> 2009 | ... N36: =SUM(N37:N38) -> 8423
B37: First Login experts | C37: 33 | D37: 46 | E37: 97 | F37: 210 | G37: 297 | H37: 582 | I37: 625 | J37: 812 | K37: 1481 | L37: 1838 | M37: 2487 | N37: 3061
B38: Repeat login experts | C38: 88 | D38: 104 | E38: 127 | F38: 176 | G38: 340 | H38: 531 | I38: 941 | J38: 1197 | K38: 1695 | L38: 2722 | M38: 3695 | N38: 5362
B40: Total Shifts | C40: 3374 | D40: 3698 | E40: 5350 | F40: 8602 | G40: 16535 | H40: 28634 | I40: 39739 | J40: 53626 | K40: 75747 | L40: 117432 | M40: 150778 | N40: 213124
B41: Total Shifts per Expert | C41: =C40/C36 -> 27.884298 | D41: =D40/D36 -> 24.653333 | E41: =E40/E36 -> 23.883929 | F41: =F40/F36 -> 22.284974 | G41: =G40/G36 -> 25.957614 | H41: =H40/H36 -> 25.726864 | I41: =I40/I36 -> 25.376117 | J41: =J40/J36 -> 26.692882 | ... N41: =N40/N36 -> 25.302624
B42: Present Shifts | C42: 2485 | D42: 2624 | E42: 3774 | F42: 6348 | G42: 10865 | H42: 19875 | I42: 27071 | J42: 36081 | K42: 53027 | L42: 82478 | M42: 110372 | N42: 160923
B43: Shifts per expert | C43: =C42/C36 -> 20.53719 | D43: =D42/D36 -> 17.493333 | E43: =E42/E36 -> 16.848214 | F43: =F42/F36 -> 16.445596 | G43: =G42/G36 -> 17.056515 | H43: =H42/H36 -> 17.857143 | I43: =I42/I36 -> 17.286718 | J43: =J42/J36 -> 17.959681 | ... N43: =N42/N36 -> 19.105188
B44: Attendence% | C44: =C42/C40 -> 0.73651452 | D44: =D42/D40 -> 0.70957274 | E44: =E42/E40 -> 0.70542056 | F44: =F42/F40 -> 0.73796791 | G44: =G42/G40 -> 0.65709102 | H44: =H42/H40 -> 0.69410491 | I44: =I42/I40 -> 0.68121996 | J44: =J42/J40 -> 0.67282661 | ... N44: =N42/N40 -> 0.75506747
B45: Shift hours | C45: 16935 | D45: 17886 | E45: 27198 | F45: 53875.81 | G45: 92848 | H45: 173757 | I45: 239593 | J45: 339942 | K45: 515685 | L45: 809604.52 | M45: 1100971 | N45: =96666701/60 -> 1611111.7
B46: Hours per shift | C46: =C45/C42 -> 6.8148893 | D46: =D45/D42 -> 6.816311 | E46: =E45/E42 -> 7.2066773 | F46: =F45/F42 -> 8.4870526 | G46: =G45/G42 -> 8.5456052 | H46: =H45/H42 -> 8.7424906 | I46: =I45/I42 -> 8.8505412 | J46: =J45/J42 -> 9.4216347 | ... N46: =N45/N42 -> 10.011693
B48: Utilization % | C48: =IFERROR(C23/C45,"") -> 0.53999114 | D48: =IFERROR(D23/D45,"") -> 0.53690037 | E48: =IFERROR(E23/E45,"") -> 0.49478822 | F48: =IFERROR(F23/F45,"") -> 0.34269554 | G48: =IFERROR(G23/G45,"") -> 0.44670321 | H48: =IFERROR(H23/H45,"") -> 0.31581461 | I48: =IFERROR(I23/I45,"") -> 0.33085065 | J48: =IFERROR(J23/J45,"") -> 0.42664337 | ... N48: =IFERROR(N23/N45,"") -> 0.40236798
...

Sheet RQSP Metrics
C2: Actual | D2: Actual | E2: Actual | F2: Actual | G2: Actual | H2: Actual | I2: Actual | J2: Actual | K2: Actual
B3: RQSP Metrics | C3: 45777 | D3: =EOMONTH(C3,1) -> 45808 | E3: =EOMONTH(D3,1) -> 45838 | F3: =EOMONTH(E3,1) -> 45869 | G3: =EOMONTH(F3,1) -> 45900 | H3: =EOMONTH(G3,1) -> 45930 | I3: =EOMONTH(H3,1) -> 45961 | J3: =EOMONTH(I3,1) -> 45991 | K3: =EOMONTH(J3,1) -> 46022
C4: 506.96274 | D4: 1134.738 | E4: 1549.1958
B5: Reliability
B6: Booking availability | G6: 0.887 | H6: 0.893 | I6: 0.814 | J6: 0.8637 | K6: 0.8845
B7: Fullfillment % | G7: 0.98289416 | H7: 0.99192785 | I7: 0.94681995 | J7: 0.994 | K7: 0.956
B9: Quality
B10: Average Rating | C10: 4.56 | D10: 4.52 | E10: 4.58 | F10: 4.63 | G10: 4.64 | H10: 4.64 | I10: 4.5710685 | J10: 4.59 | K10: 4.6039875
B11: 5 Rating % | C11: 0.77925834 | D11: 0.77925834 | E11: 0.7871776 | F11: 0.80329931 | G11: 0.8034 | H11: 0.84 | I11: 0.7795 | J11: 0.78625 | K11: 0.7953
B12: 4 Rating % | C12: 0.10226216 | D12: 0.0997 | E12: 0.0995796 | F12: 0.098554114 | G12: 0.0977 | H12: 0.1 | I12: 0.1069 | J12: 0.1047 | K12: 0.1002
B13: 3 Rating % | C13: 0.050924491 | D13: 0.054 | E13: 0.0546478 | F13: 0.049471968 | G13: 0.0492 | H13: 0.01 | I13: 0.0549 | J13: 0.05359 | K13: 0.0508
B14: 2 Rating % | C14: 0.030781944 | D14: 0.0305 | E14: 0.0223684 | F14: 0.01917216 | G14: 0.0202 | H14: 0.02 | I14: 0.0227 | J14: 0.02134 | K14: 0.0202
B15: 1 Rating % | C15: 0.036773061 | D15: 0.0401 | E15: 0.0362266 | F15: 0.029502445 | G15: 0.0296 | H15: 0.03 | I15: 0.0361 | J15: 0.03411 | K15: 0.0333
B17: Speed
B18: Median (P50)
B19: Booking to Check-in | C19: 19.31 | D19: 19.25 | E19: 19.22 | F19: 18.07 | G19: 18.12 | H19: 17.87 | I19: 19.58 | J19: 18.083333 | K19: 17.48333
B20: Booking to Allocation | C20: 0.02 | D20: 0.05 | E20: 0.12 | F20: 0.13 | G20: 0.12 | H20: 0.07 | I20: 0.05 | J20: 0.03 | K20: 0.05
B21: Allocation to Acceptance | C21: 1.18 | D21: 0.98 | E21: 0.48 | F21: 0.42 | G21: 0.4 | H21: 0.35 | I21: 0.4 | J21: 0.48 | K21: 0.37
B22: Acceptance to Arrival | C22: 10.18 | D22: 8.93 | E22: 8.43 | F22: 7.65 | G22: 7.08 | H22: 6.6 | I22: 7.35 | J22: 7.42 | K22: 7.58
B23: Arrival to Check-in | C23: 2.88 | D23: 5.52 | E23: 6.6 | F23: 6.9 | G23: 7.9 | H23: 8.62 | I23: 8.7 | J23: 7.12 | K23: 6.8
B25: 90th Percentile (P90)
B26: Booking to Check-in | C26: 45.6 | D26: 47 | E26: 37.49 | F26: 33.98 | G26: 36.35 | H26: 34.79 | I26: 42.68 | J26: 37.316667 | K26: 33.81667
B27: Booking to Allocation | C27: 12.932 | D27: 11.456 | E27: 8 | F27: 5.63 | G27: 6.07 | H27: 4.768 | I27: 7.03 | J27: 0.17 | K27: 7.08
B28: Allocation to Acceptance | C28: 10.957 | D28: 8.13 | E28: 3.03 | F28: 2.68 | G28: 2.68 | H28: 1.88 | I28: 4.1 | J28: 11.03 | K28: 2.1
B29: Acceptance to Arrival | C29: 22.953 | D29: 21.43 | E29: 18.52 | F29: 16.37 | G29: 15.38 | H29: 14.98 | I29: 16.78 | J29: 16.13 | K29: 16.33
B30: Arrival to Check-in | C30: 10.23 | D30: 13.744 | E30: 15.1 | F30: 15.754 | G30: 17.72 | H30: 19.55 | I30: 20.47 | J30: 16.5 | K30: 15.58
B32: Punctuality
B33: % Jobs On Time | C33: 0.451 | D33: 0.411 | E33: 0.465 | F33: 0.526 | G33: 0.533 | H33: 0.546 | I33: 0.444 | J33: =1-J34-J35 -> 0.5421261 | K33: =1-K34-K35 -> 0.6509
B34: % EOB (5-15) | C34: 0.21618196 | D34: 0.23169831 | E34: 0.26160168 | F34: 0.26449153 | G34: 0.23397414 | H34: 0.23865645 | I34: 0.2024272 | J34: 0.2114739 | K34: 0.206
B35: % EOB >15 | C35: 0.333111 | D35: 0.3571388 | E35: 0.2736958 | F35: 0.2095901 | G35: 0.2326695 | H35: 0.2158295 | I35: 0.3534045 | J35: 0.2464 | K35: 0.1431

Sheet Customer Cohorts - Overall 
B2: Customer Retention
B3: Month | C3: FTs | D3: 30 | E3: 60 | F3: 90 | G3: 120 | H3: 150 | I3: 180 | J3: 210 | K3: 240 | L3: 270 | M3: 300 | N3: 360 | Q3: The current rate reflects customers acquired in October who placed a second order within the same month. Since the 30-day period isn’t complete, retention is expected to improve.
B4: 45658 | C4: 997 | D4: 0.43 | E4: 0.34 | F4: 0.31 | G4: 0.3 | H4: 0.29 | I4: 0.29 | J4: 0.31 | K4: 0.29 | L4: 0.28 | M4: 0.31159 | N4: 0.29
B5: 45689 | C5: 1534 | D5: 0.39 | E5: 0.31 | F5: 0.28 | G5: 0.27 | H5: 0.28 | I5: 0.31 | J5: 0.29 | K5: 0.3 | L5: 0.3108 | M5: 0.28427
B6: 45717 | C6: 2546 | D6: 0.37 | E6: 0.24 | F6: 0.25 | G6: 0.24 | H6: 0.24 | I6: 0.26 | J6: 0.27 | K6: 0.27218 | L6: 0.25727
B7: 45748 | C7: 3787 | D7: 0.58 | E7: 0.28 | F7: 0.26 | G7: 0.27 | H7: 0.27 | I7: 0.27 | J7: 0.29403 | K7: 0.27099
B8: 45778 | C8: 9361 | D8: 0.79 | E8: 0.25 | F8: 0.25 | G8: 0.26 | H8: 0.26 | I8: 0.27266 | J8: 0.28148
B9: 45809 | C9: 11532 | D9: 0.76 | E9: 0.27 | F9: 0.26 | G9: 0.26 | H9: 0.27884 | I9: 0.27779
B10: 45839 | C10: 17911 | D10: 0.74 | E10: 0.26 | F10: 0.25 | G10: 0.26358 | H10: 0.26582
B11: 45870 | C11: 34709 | D11: 0.72 | E11: 0.27 | F11: 0.27896 | G11: 0.2767
B12: 45901 | C12: 48045 | D12: 0.68 | E12: 0.32081 | F12: 0.29341
B13: =EOMONTH(B12,1) -> 45961 | C13: 82760 | D13: 0.67978 | E13: 0.28012
B14: =EOMONTH(B13,1) -> 45991 | C14: ='Key Metrics'!M12 -> 86837 | D14: 0.71161
B15: =EOMONTH(B14,1) -> 46022 | C15: ='Key Metrics'!N12 -> 102395 | D15: 0.54132
B17: Booking Retention
B18: Month | C18: FTs | D18: 30 | E18: 60 | F18: 90 | G18: 120 | H18: 150 | I18: 180 | J18: 210 | K18: 240 | L18: 270 | M18: 300 | N18: 360
B19: 45658 | C19: 997 | D19: =D49*D4 -> 1.1126379 | E19: =E49*E4 -> 0.7923122 | F19: =F49*F4 -> 0.7107556 | G19: =G49*G4 -> 0.766782 | H19: =H49*H4 -> 0.77749 | I19: =I49*I4 -> 0.7239705 | J19: =J49*J4 -> 0.8138802 | K19: =K49*K4 -> 0.7485567 | ... N19: =N49*N4 -> 1.03907
B20: 45689 | C20: 1534 | D20: =D50*D5 -> 1.0026744 | E20: =E50*E5 -> 0.6840274 | F20: =F50*F5 -> 0.7183148 | G20: =G50*G5 -> 0.6794361 | H20: =H50*H5 -> 0.7075684 | I20: =I50*I5 -> 0.7781899 | J20: =J50*J5 -> 0.8611753 | K20: =K50*K5 -> 0.811464 | ... M20: =M50*M5 -> 0.9267202
B21: 45717 | C21: 2546 | D21: =D51*D6 -> 0.8894097 | E21: =E51*E6 -> 0.578736 | F21: =F51*F6 -> 0.5593975 | G21: =G51*G6 -> 0.5498784 | H21: =H51*H6 -> 0.5802432 | I21: =I51*I6 -> 0.7094334 | J21: =J51*J6 -> 0.7319106 | K21: =K51*K6 -> 0.83450388 | L21: =L51*L6 -> 0.78595985
B22: 45748 | C22: 3787 | D22: =D52*D7 -> 1.4608518 | E22: =E52*E7 -> 0.665434 | F22: =F52*F7 -> 0.5820932 | G22: =G52*G7 -> 0.6462666 | H22: =H52*H7 -> 0.7054992 | I22: =I52*I7 -> 0.7030287 | J22: =J52*J7 -> 0.88826463 | K22: =K52*K7 -> 0.8644581
B23: 45778 | C23: 9361 | D23: =D53*D8 -> 1.8961817 | E23: =E53*E8 -> 0.5591125 | F23: =F53*F8 -> 0.56955 | G23: =G53*G8 -> 0.6506058 | H23: =H53*H8 -> 0.63375 | I23: =I53*I8 -> 0.7579948 | J23: =J53*J8 -> 0.82952156
B24: 45809 | C24: 11532 | D24: =D54*D9 -> 1.7528336 | E24: =E54*E9 -> 0.6140502 | F24: =F54*F9 -> 0.6249074 | G24: =G54*G9 -> 0.6443554 | H24: =H54*H9 -> 0.74199324 | I24: =I54*I9 -> 0.77308957
B25: 45839 | C25: 17911 | D25: =D55*D10 -> 1.6568008 | E25: =E55*E10 -> 0.5914662 | F25: =F55*F10 -> 0.59315 | G25: =G55*G10 -> 0.7090302 | H25: =H55*H10 -> 0.75997938
B26: 45870 | C26: 34709 | D26: =D56*D11 -> 1.674972 | E26: =E56*E11 -> 0.6544314 | F26: =F56*F11 -> 0.71999576 | G26: =G56*G11 -> 0.7612017
B27: 45901 | C27: 48045 | D27: =D57*D12 -> 1.6156732 | E27: =E57*E12 -> 0.79657123 | F27: =F57*F12 -> 0.81157206
B28: =EOMONTH(B27,1) -> 45961 | C28: =C13 -> 82760 | D28: =D58*D13 -> 1.6457474 | E28: =E58*E13 -> 0.73279392
B29: =EOMONTH(B28,1) -> 45991 | C29: =C14 -> 86837 | D29: =D59*D14 -> 1.8416467
B30: =EOMONTH(B29,1) -> 46022 | C30: =C15 -> 102395 | D30: =D60*D15 -> 1.1535529
B32: Average Revenue Per User
B33: Month | C33: FTs | D33: 30 | E33: 60 | F33: 90 | G33: 120 | H33: 150 | I33: 180 | J33: 210 | K33: 240 | L33: 270 | M33: 300 | N33: 360
B34: 45658 | C34: 997 | D34: 622.73125 | E34: 560.463 | F34: 543.85099 | G34: 606.19668 | H34: 620.63602 | I34: 565.70819 | J34: 568.8386 | K34: 583.528 | L34: 671.151 | M34: 865.235 | N34: 844.297
B35: 45689 | C35: 1534 | D35: 602.35718 | E35: 505.71564 | F35: 599.69641 | G35: 561.19277 | H35: 543.49061 | I35: 514.66718 | J35: 669.117 | K35: 673.342 | L35: 748.577 | M35: 746.958
B36: 45717 | C36: 2546 | D36: 549.01505 | E36: 571.2223 | F36: 504.64815 | G36: 511.14697 | H36: 508.89439 | I36: 615.432 | J36: 665.233 | K36: 763.783 | L36: 726.243
B37: 45748 | C37: 3787 | D37: 546.37557 | E37: 527.6976 | F37: 497.86253 | G37: 495.7739 | H37: 589.072 | I37: 646.292 | J37: 707.75 | K37: 744.083
B38: 45778 | C38: 9361 | D38: 478.63597 | E38: 490.54682 | F38: 491.66711 | G38: 562.223 | H38: 601.551 | I38: 657.623 | J38: 659.977
B39: 45809 | C39: 11532 | D39: 457.11097 | E39: 478.47329 | F39: 533.887 | G39: 595.462 | H39: 602.881 | I39: 611.861
B40: 45839 | C40: 17911 | D40: 436.795 | E40: 518.266 | F40: 579.719 | G40: 638.087 | H40: 646.584
B41: 45870 | C41: 34709 | D41: 470.447 | E41: 591.007 | F41: 595.197 | G41: 616.558
B42: 45901 | C42: 48045 | D42: 515.24 | E42: 565.93 | F42: 613.512
B43: =B28 -> 45961 | C43: =C28 -> 82760 | D43: 536.756 | E43: 592.036
...

Sheet Financials ->

Sheet MIS P&L
B2: Jobs | C2: ='Key Metrics'!C14 -> 6863 | D2: ='Key Metrics'!D14 -> 7519 | E2: ='Key Metrics'!E14 -> 10642 | F2: ='Key Metrics'!F14 -> 14980 | G2: ='Key Metrics'!G14 -> 35189 | H2: ='Key Metrics'!H14 -> 47211 | I2: ='Key Metrics'!I14 -> 68196 | J2: ='Key Metrics'!J14 -> 118808 | ... N2: ='Key Metrics'!N14 -> 518345
B3: Hours | C3: ='Key Metrics'!C23 -> 9144.75 | D3: ='Key Metrics'!D23 -> 9603 | E3: ='Key Metrics'!E23 -> 13457.25 | F3: ='Key Metrics'!F23 -> 18463 | G3: ='Key Metrics'!G23 -> 41475.5 | H3: ='Key Metrics'!H23 -> 54875 | I3: ='Key Metrics'!I23 -> 79269.5 | J3: ='Key Metrics'!J23 -> 145034 | ... N3: ='Key Metrics'!N23 -> 648259.75
B5: Profit & Loss Statement | C5: Actual | D5: Actual | E5: Actual | F5: Actual | G5: Actual | H5: Actual | I5: Actual | J5: Actual | K5: Actual | L5: Actual | M5: Actual | N5: Actual
B6: All Values (in INR Thousands) | C6: 45658 | D6: 45689 | E6: 45717 | F6: 45748 | G6: 45778 | H6: 45809 | I6: 45839 | J6: 45870 | K6: 45901 | L6: 45931 | M6: 45962 | N6: 45992
B7: Revenue | C7: =-SUMIF('TB 0125'!H:H,'MIS P&L'!B7,'TB 0125'!F:F)+C10 -> 1685.4178 | D7: =-SUMIF('TB 0225'!H:H,'MIS P&L'!B7,'TB 0225'!F:F)+D10 -> 1752.6994 | E7: =-SUMIF('TB 0325'!H:H,'MIS P&L'!B7,'TB 0325'!F:F)+E10 -> 2454.9928 | F7: =-SUMIF('TB 0425'!H:H,'MIS P&L'!B7,'TB 0425'!F:F)+F10 -> 3379.7516 | G7: =-SUMIF('TB 0525'!H:H,'MIS P&L'!B7,'TB 0525'!F:F)+G10-752 -> 7565.0949 | H7: =-SUMIF('TB 0625'!H:H,'MIS P&L'!B7,'TB 0625'!F:F)+H10 -> 10327.934 | I7: =-SUMIF('TB 0725'!H:H,'MIS P&L'!B7,'TB 0725'!F:F)+I10 -> 14930.412 | J7: =-SUMIF('TB 0825'!H:H,'MIS P&L'!B7,'TB 0825'!F:F)+J10 -> 27555.775 | K7: =-SUMIF('TB 0925'!H:H,'MIS P&L'!B7,'TB 0925'!F:F)+K10 -> 37606.66 | L7: =-SUMIF('TB 1025'!H:H,'MIS P&L'!B7,'TB 1025'!F:F)+L10 -> 74251.551 | M7: =-SUMIF('TB 1125'!H:H,'MIS P&L'!B7,'TB 1125'!F:F)+M10-'TB 1125'!P6/10^3 -> 84625.473 | N7: =-SUMIF('TB 1225'!H:H,'MIS P&L'!B7,'TB 1225'!F:F)+N10-('TB 1225'!P6-'TB 1225'!P7)/10^3 -> 116769.39
B8: Service Cost | C8: =SUMIF('TB 0125'!H:H,'MIS P&L'!B8,'TB 0125'!F:F) -> 1316.7668 | D8: =SUMIF('TB 0225'!H:H,'MIS P&L'!B8,'TB 0225'!F:F)+SUMIF('TB 0225'!H:H,"Service Cost - Retention Bonus",'TB 0225'!F:F) -> 1808.5563 | E8: =SUMIF('TB 0325'!H:H,'MIS P&L'!B8,'TB 0325'!F:F) -> 2377.6725 | F8: =SUMIF('TB 0425'!H:H,'MIS P&L'!B8,'TB 0425'!F:F) -> 4666.3881 | G8: =SUMIF('TB 0525'!H:H,'MIS P&L'!B8,'TB 0525'!F:F)+SUMIF('TB 0525'!H:H,"Service Cost - Retention Bonus",'TB 0525'!F:F) -> 10125.432 | H8: =SUMIF('TB 0625'!H:H,'MIS P&L'!B8,'TB 0625'!F:F) -> 16194.053 | I8: =SUMIF('TB 0725'!H:H,'MIS P&L'!B8,'TB 0725'!F:F) -> 20797.581 | J8: =SUMIF('TB 0825'!H:H,'MIS P&L'!B8,'TB 0825'!F:F) -> 34898.162 | K8: =SUMIF('TB 0925'!H:H,'MIS P&L'!B8,'TB 0925'!F:F) -> 42682.555 | L8: =SUMIF('TB 1025'!H:H,'MIS P&L'!B8,'TB 1025'!F:F) -> 80446.599 | M8: =SUMIF('TB 1125'!H:H,'MIS P&L'!B8,'TB 1125'!F:F)+1369000/10^3 -> 93364.573 | N8: =SUMIF('TB 1225'!H:H,'MIS P&L'!B8,'TB 1225'!F:F)+(2942373-123559)/10^3 -> 135426.75
B10: GST | C10: =111458.172629155/1000 -> 111.45817 | D10: =107088.778644068/1000 -> 107.08878 | E10: =145719.332747025/1000 -> 145.71933 | F10: 219.01183 | G10: =497429.94/10^3 -> 497.42994 | H10: =(679045.32-4262)/10^3 -> 674.78332 | I10: =993199.47 /10^3 -> 993.19947 | J10: 1826.7527 | K10: 2192.292 | L10: 3096.4967 | M10: =('TB 1125'!P5)/10^3 -> 3640.6934 | N10: =('TB 1225'!P5)/10^3 -> 5073.8874
B11: Promotional Discount | C11: =47693/1000 -> 47.693 | D11: =68323/1000 -> 68.323 | E11: =SUMIF('TB 0325'!H:H,'MIS P&L'!B11,'TB 0325'!F:F) -> 21.936 | F11: 33.51 | G11: 19.7 | H11: 43.827 | I11: 347.81305 | J11: 1169.488 | K11: 2266.901 | L11: 8631.1562 | M11: 12771.043 | N11: 20491.281
B12: Payment Gateway Cost | C12: =SUMIF('TB 0125'!H:H,'MIS P&L'!B12,'TB 0125'!F:F) -> 18.29068 | D12: =SUMIF('TB 0225'!H:H,'MIS P&L'!B12,'TB 0225'!F:F) -> 17.08784 | E12: =SUMIF('TB 0325'!H:H,'MIS P&L'!B12,'TB 0325'!F:F) -> 21.41301 | F12: =SUMIF('TB 0425'!H:H,'MIS P&L'!B12,'TB 0425'!F:F) -> 32.4381 | G12: =SUMIF('TB 0525'!H:H,'MIS P&L'!B12,'TB 0525'!F:F) -> 23.14003 | H12: =SUMIF('TB 0625'!H:H,'MIS P&L'!B12,'TB 0625'!F:F) -> 33.76314 | I12: =SUMIF('TB 0725'!H:H,'MIS P&L'!B12,'TB 0725'!F:F) -> 46.5271 | J12: =SUMIF('TB 0825'!H:H,'MIS P&L'!B12,'TB 0825'!F:F) -> 49.71843 | K12: =SUMIF('TB 0925'!H:H,'MIS P&L'!B12,'TB 0925'!F:F) -> 59.90393 | L12: =SUMIF('TB 1025'!H:H,'MIS P&L'!B12,'TB 1025'!F:F) -> 92.65611 | M12: =SUMIF('TB 1125'!H:H,'MIS P&L'!B12,'TB 1125'!F:F) -> 115.36249 | N12: =SUMIF('TB 1225'!H:H,'MIS P&L'!B12,'TB 1225'!F:F) -> 173.99614
B14: Gross Profit | C14: =C7-C8-C10-C11-C12 -> 191.20923 | D14: =D7-D8-D10-D11-D12 -> -248.35645 | E14: =E7-E8-E10-E11-E12 -> -111.74799 | F14: =F7-F8-F10-F11-F12 -> -1571.5964 | G14: =G7-G8-G10-G11-G12 -> -3100.6073 | H14: =H7-H8-H10-H11-H12 -> -6618.493 | I14: =I7-I8-I10-I11-I12 -> -7254.709 | J14: =J7-J8-J10-J11-J12 -> -10388.346 | ... N14: =N7-N8-N10-N11-N12 -> -44396.531
B15: Gross Profit % | C15: =C14/C7 -> 0.11344916 | D15: =D14/D7 -> -0.1416994 | E15: =E14/E7 -> -0.045518663 | F15: =F14/F7 -> -0.46500352 | G15: =G14/G7 -> -0.40985703 | H15: =H14/H7 -> -0.64083419 | I15: =I14/I7 -> -0.48590146 | J15: =J14/J7 -> -0.37699343 | ... N15: =N14/N7 -> -0.38020694
B17: Training Centre Expenses | C17: =SUMIF('TB 0125'!H:H,'MIS P&L'!B17,'TB 0125'!F:F)+'TB 0125'!R8 -> 154.42806 | D17: =SUMIF('TB 0225'!H:H,'MIS P&L'!B17,'TB 0225'!F:F)+'TB 0225'!P8 -> 555.65933 | E17: =SUMIF('TB 0325'!H:H,'MIS P&L'!B17,'TB 0325'!F:F)+'TB 0325'!P7 -> 378.59594 | F17: =SUMIF('TB 0425'!H:H,'MIS P&L'!B17,'TB 0425'!F:F)+'TB 0425'!R7 -> 1071.6243 | G17: =SUMIF('TB 0525'!H:H,'MIS P&L'!B17,'TB 0525'!F:F)+'TB 0525'!R4-28 -> 2121.5457 | H17: =SUMIF('TB 0625'!H:H,'MIS P&L'!B17,'TB 0625'!F:F)+'TB 0625'!M5 -> 1839.1313 | I17: =SUMIF('TB 0725'!H:H,'MIS P&L'!B17,'TB 0725'!F:F)+'TB 0725'!L5 -> 2130.1765 | J17: =SUMIF('TB 0825'!H:H,'MIS P&L'!B17,'TB 0825'!F:F)+'TB 0825'!L5 -> 2395.6542 | K17: =SUMIF('TB 0925'!H:H,'MIS P&L'!B17,'TB 0925'!F:F)+'TB 0925'!M6 -> 2327.5014 | L17: =SUMIF('TB 1025'!H:H,'MIS P&L'!B17,'TB 1025'!F:F)+'TB 1025'!M6 -> 4509.7977 | M17: =SUMIF('TB 1125'!H:H,'MIS P&L'!B17,'TB 1125'!F:F)+'TB 1125'!M6 -> 4659.3912 | N17: =SUMIF('TB 1225'!H:H,'MIS P&L'!B17,'TB 1225'!F:F)+'TB 1225'!M6 -> 5498.3315
B18: Managerial Cost | C18: =SUMIF('TB 0125'!H:H,'MIS P&L'!B18,'TB 0125'!F:F)+'TB 0125'!R4 -> 135.548 | D18: =SUMIF('TB 0225'!H:H,'MIS P&L'!B18,'TB 0225'!F:F)+'TB 0225'!P4 -> 249.681 | E18: =SUMIF('TB 0325'!H:H,'MIS P&L'!B18,'TB 0325'!F:F)+'TB 0325'!P3 -> 436.977 | F18: =SUMIF('TB 0425'!H:H,'MIS P&L'!B18,'TB 0425'!F:F)+'TB 0425'!R3 -> 913.946 | G18: =SUMIF('TB 0525'!H:H,'MIS P&L'!B18,'TB 0525'!F:F)+'TB 0525'!R6 -> 1372.664 | H18: =SUMIF('TB 0625'!H:H,'MIS P&L'!B18,'TB 0625'!F:F)+'TB 0625'!M6 -> 1974.5513 | I18: =SUMIF('TB 0725'!H:H,'MIS P&L'!B18,'TB 0725'!F:F)+'TB 0725'!L4 -> 2871.9352 | J18: =SUMIF('TB 0825'!H:H,'MIS P&L'!B18,'TB 0825'!F:F)+'TB 0825'!L4 -> 4358.6587 | K18: =SUMIF('TB 0925'!H:H,'MIS P&L'!B18,'TB 0925'!F:F)+'TB 0925'!M4 -> 5433.6316 | L18: =SUMIF('TB 1025'!H:H,'MIS P&L'!B18,'TB 1025'!F:F)+'TB 1025'!M4 -> 5889.8775 | M18: =SUMIF('TB 1125'!H:H,'MIS P&L'!B18,'TB 1125'!F:F)+'TB 1125'!M4 -> 5830.2844 | N18: =SUMIF('TB 1225'!H:H,'MIS P&L'!B18,'TB 1225'!F:F)+'TB 1225'!M4 -> 7442.0085
B19: Sourcing & Onboarding Cost | C19: =SUMIF('TB 0125'!H:H,'MIS P&L'!B19,'TB 0125'!F:F)+'TB 0125'!R7 -> 265.24942 | D19: =SUMIF('TB 0225'!H:H,'MIS P&L'!B19,'TB 0225'!F:F)+'TB 0225'!P7 -> 489.45735 | E19: =SUMIF('TB 0325'!H:H,'MIS P&L'!B19,'TB 0325'!F:F)+'TB 0325'!P6 -> 968.60079 | F19: =SUMIF('TB 0425'!H:H,'MIS P&L'!B19,'TB 0425'!F:F)+'TB 0425'!R6 -> 1469.4468 | G19: =SUMIF('TB 0525'!H:H,'MIS P&L'!B19,'TB 0525'!F:F)+'TB 0525'!R7 -> 1820.524 | H19: =SUMIF('TB 0625'!H:H,'MIS P&L'!B19,'TB 0625'!F:F)+'TB 0625'!M4 -> 4666.5157 | I19: =SUMIF('TB 0725'!H:H,'MIS P&L'!B19,'TB 0725'!F:F)+'TB 0725'!L6 -> 4715.0503 | J19: =SUMIF('TB 0825'!H:H,'MIS P&L'!B19,'TB 0825'!F:F)+'TB 0825'!L6 -> 6769.6192 | K19: =SUMIF('TB 0925'!H:H,'MIS P&L'!B19,'TB 0925'!F:F)+'TB 0925'!M5 -> 9609.5003 | L19: =SUMIF('TB 1025'!H:H,'MIS P&L'!B19,'TB 1025'!F:F)+'TB 1025'!M5 -> 13533.116 | M19: =SUMIF('TB 1125'!H:H,'MIS P&L'!B19,'TB 1125'!F:F)+'TB 1125'!M5-1369000/10^3 -> 13377.681 | N19: =SUMIF('TB 1225'!H:H,'MIS P&L'!B19,'TB 1225'!F:F)+'TB 1225'!M5-(2942373-123559)/10^3 -> 17626.83
B20: Customer Success Cost | C20: =SUMIF('TB 0125'!H:H,'MIS P&L'!B20,'TB 0125'!F:F)+'TB 0125'!R6 -> 77.612 | D20: =SUMIF('TB 0225'!H:H,'MIS P&L'!B20,'TB 0225'!F:F)+'TB 0225'!P6 -> 54 | E20: =SUMIF('TB 0325'!H:H,'MIS P&L'!B20,'TB 0325'!F:F)+'TB 0325'!P5 -> 214.423 | F20: =SUMIF('TB 0425'!H:H,'MIS P&L'!B20,'TB 0425'!F:F)+'TB 0425'!R5 -> 351.328 | G20: =SUMIF('TB 0525'!H:H,'MIS P&L'!B20,'TB 0525'!F:F)+'TB 0525'!R5 -> 622.162 | H20: =SUMIF('TB 0625'!H:H,'MIS P&L'!B20,'TB 0625'!F:F)+'TB 0625'!M7 -> 689.12637 | I20: =SUMIF('TB 0725'!H:H,'MIS P&L'!B20,'TB 0725'!F:F)+'TB 0725'!L7 -> 653.00077 | J20: =SUMIF('TB 0825'!H:H,'MIS P&L'!B20,'TB 0825'!F:F)+'TB 0825'!L7 -> 772.37655 | K20: =SUMIF('TB 0925'!H:H,'MIS P&L'!B20,'TB 0925'!F:F)+'TB 0925'!M3 -> 872.25708 | L20: =SUMIF('TB 1025'!H:H,'MIS P&L'!B20,'TB 1025'!F:F)+'TB 1025'!M3 -> 1664.9577 | M20: =SUMIF('TB 1125'!H:H,'MIS P&L'!B20,'TB 1125'!F:F)+'TB 1125'!M3 -> 2306.0512 | N20: =SUMIF('TB 1225'!H:H,'MIS P&L'!B20,'TB 1225'!F:F)+'TB 1225'!M3 -> 2942.72
B21: Operational Cost | C21: 0 | D21: 0 | E21: 0 | F21: =SUMIF('TB 0425'!H:H,'MIS P&L'!B21,'TB 0425'!F:F) -> 99.31976 | G21: =SUMIF('TB 0525'!H:H,'MIS P&L'!B21,'TB 0525'!F:F)+28 -> 468.69315 | H21: =SUMIF('TB 0625'!H:H,'MIS P&L'!B21,'TB 0625'!F:F) -> 1297.7536 | I21: =SUMIF('TB 0725'!H:H,'MIS P&L'!B21,'TB 0725'!F:F) -> 2435.4273 | J21: =SUMIF('TB 0825'!H:H,'MIS P&L'!B21,'TB 0825'!F:F) -> 1928.288 | K21: =SUMIF('TB 0925'!H:H,'MIS P&L'!B21,'TB 0925'!F:F) -> 725.32188 | L21: =SUMIF('TB 1025'!H:H,'MIS P&L'!B21,'TB 1025'!F:F) -> 1037.1374 | M21: =SUMIF('TB 1125'!H:H,'MIS P&L'!B21,'TB 1125'!F:F) -> 1046.1692 | N21: =SUMIF('TB 1225'!H:H,'MIS P&L'!B21,'TB 1225'!F:F) -> 725.16
B23: Operating Profit | C23: =C14-SUM(C17:C21) -> -441.62825 | D23: =D14-SUM(D17:D21) -> -1597.1541 | E23: =E14-SUM(E17:E21) -> -2110.3447 | F23: =F14-SUM(F17:F21) -> -5477.2612 | G23: =G14-SUM(G17:G21) -> -9506.1962 | H23: =H14-SUM(H17:H21) -> -17085.571 | I23: =I14-SUM(I17:I21) -> -20060.299 | J23: =J14-SUM(J17:J21) -> -26612.943 | ... N23: =N14-SUM(N17:N21) -> -78631.581
B24: Operating Profit % | C24: =C23/C7 -> -0.26202894 | D24: =D23/D7 -> -0.91125387 | E24: =E23/E7 -> -0.8596134 | F24: =F23/F7 -> -1.6206106 | G24: =G23/G7 -> -1.2565865 | H24: =H23/H7 -> -1.6543068 | I24: =I23/I7 -> -1.3435864 | J24: =J23/J7 -> -0.96578458 | ... N24: =N23/N7 -> -0.67339208
B26: Marketing Cost | C26: =SUM(C27:C29) -> 876.16473 | D26: =SUM(D27:D29) -> 1322.9 | E26: =SUM(E27:E29) -> 1588.0344 | F26: =SUM(F27:F29) -> 2636.4766 | G26: =SUM(G27:G29) -> 6211.2232 | H26: =SUM(H27:H29) -> 10479.127 | I26: =SUM(I27:I29) -> 17024.858 | J26: =SUM(J27:J29) -> 35615.457 | ... N26: =SUM(N27:N29) -> 90196.321
B27: Customer Acquisition Cost (Digital & BTL Marketing) | C27: =SUMIF('TB 0125'!H:H,'MIS P&L'!B27,'TB 0125'!F:F)+'TB 0125'!R5 -> 611.77973 | D27: =SUMIF('TB 0225'!H:H,'MIS P&L'!B27,'TB 0225'!F:F)+'TB 0225'!P5 -> 669.825 | E27: =SUMIF('TB 0325'!H:H,'MIS P&L'!B27,'TB 0325'!F:F)+'TB 0325'!P4 -> 863.641 | F27: =SUMIF('TB 0425'!H:H,'MIS P&L'!B27,'TB 0425'!F:F)+'TB 0425'!R4 -> 1339.3396 | G27: =SUMIF('TB 0525'!H:H,'MIS P&L'!B27,'TB 0525'!F:F) -> 3005.0652 | H27: =SUMIF('TB 0625'!H:H,'MIS P&L'!B27,'TB 0625'!F:F) -> 5817.5286 | I27: =SUMIF('TB 0725'!H:H,'MIS P&L'!B27,'TB 0725'!F:F) -> 7135.4089 | J27: =SUMIF('TB 0825'!H:H,'MIS P&L'!B27,'TB 0825'!F:F) -> 17875.963 | K27: =SUMIF('TB 0925'!H:H,'MIS P&L'!B27,'TB 0925'!F:F) -> 23474.935 | L27: =SUMIF('TB 1025'!H:H,'MIS P&L'!B27,'TB 1025'!F:F) -> 21563.45 | M27: =SUMIF('TB 1125'!H:H,'MIS P&L'!B27,'TB 1125'!F:F) -> 31021.673 | N27: =SUMIF('TB 1225'!H:H,'MIS P&L'!B27,'TB 1225'!F:F) -> 39731.204
B28: Branding Expense | C28: =SUMIF('TB 0125'!H:H,'MIS P&L'!B28,'TB 0125'!F:F) -> 81.59 | D28: =SUMIF('TB 0225'!H:H,'MIS P&L'!B28,'TB 0225'!F:F) -> 351.67 | E28: =SUMIF('TB 0325'!H:H,'MIS P&L'!B28,'TB 0325'!F:F) -> 68.02636 | F28: =SUMIF('TB 0425'!H:H,'MIS P&L'!B28,'TB 0425'!F:F) -> 427.385 | G28: =SUMIF('TB 0525'!H:H,'MIS P&L'!B28,'TB 0525'!F:F) -> 395 | H28: =SUMIF('TB 0625'!H:H,'MIS P&L'!B28,'TB 0625'!F:F) -> 576.15 | I28: =SUMIF('TB 0725'!H:H,'MIS P&L'!B28,'TB 0725'!F:F) -> 4461.049 | J28: =SUMIF('TB 0825'!H:H,'MIS P&L'!B28,'TB 0825'!F:F) -> 9270.918 | K28: =SUMIF('TB 0925'!H:H,'MIS P&L'!B28,'TB 0925'!F:F) -> 6044.993 | L28: =SUMIF('TB 1025'!H:H,'MIS P&L'!B28,'TB 1025'!F:F) -> 13300 | M28: =SUMIF('TB 1125'!H:H,'MIS P&L'!B28,'TB 1125'!F:F) -> 12253.526 | N28: =SUMIF('TB 1225'!H:H,'MIS P&L'!B28,'TB 1225'!F:F) -> 16041.3
B29: New User Discount (incl. Early Lifecycle Coupons & Referral Discount) | C29: =SUMIF('TB 0125'!H:H,'MIS P&L'!B29,'TB 0125'!F:F)+(79586/1000) -> 182.795 | D29: =SUMIF('TB 0225'!H:H,'MIS P&L'!B29,'TB 0225'!F:F)+(183118/1000) -> 301.405 | E29: =SUMIF('TB 0325'!H:H,'MIS P&L'!B29,'TB 0325'!F:F) -> 656.367 | F29: =SUMIF('TB 0425'!H:H,'MIS P&L'!B29,'TB 0425'!F:F)+(771680/1000) -> 869.752 | G29: =SUMIF('TB 0525'!H:H,'MIS P&L'!B29,'TB 0525'!F:F)+3344.989-752 -> 2811.158 | H29: =SUMIF('TB 0625'!H:H,'MIS P&L'!B29,'TB 0625'!F:F)+(5295962/10^3) -> 4085.448 | I29: =SUMIF('TB 0725'!H:H,'MIS P&L'!B29,'TB 0725'!F:F)+(6771408/10^3)+194.334 -> 5428.4001 | J29: =SUMIF('TB 0825'!H:H,'MIS P&L'!B29,'TB 0825'!F:F)+(9030.74944)+(34.71)+1714.962 -> 8468.5754 | K29: =SUMIF('TB 0925'!H:H,'MIS P&L'!B29,'TB 0925'!F:F)+(10998155/10^3)+4768.292 -> 13344.87 | L29: =SUMIF('TB 1025'!H:H,'MIS P&L'!B29,'TB 1025'!F:F)+(17286475.84/10^3)+14447.575 -> 28938.289 | M29: =('TB 1125'!S6/10^3)+SUMIF('TB 1125'!H:H,'MIS P&L'!B29,'TB 1125'!F:F)-'TB 1125'!P6/10^3+17129.742 -> 28419.663 | N29: =SUMIF('TB 1225'!H:H,'MIS P&L'!B29,'TB 1225'!F:F)+('TB 1225'!S6+'TB 1225'!S7)/10^3-('TB 1225'!P6-'TB 1225'!P7)/10^3+20790.947 -> 34423.818
B30: Employee Cost | C30: =SUM(C31:C32) -> 3092.8646 | D30: =SUM(D31:D32) -> 6606.2401 | E30: =SUM(E31:E32) -> 9142.0608 | F30: =SUM(F31:F32) -> 12823.778 | G30: =SUM(G31:G32) -> 16357.029 | H30: =SUM(H31:H32) -> 19256.697 | I30: =SUM(I31:I32) -> 22548.296 | J30: =SUM(J31:J32) -> 24500.942 | ... N30: =SUM(N31:N32) -> 45768.018
B31: Employee Cost | C31: =SUMIF('TB 0125'!H:H,'MIS P&L'!B30,'TB 0125'!F:F)+'TB 0125'!R3 -> 3092.8646 | D31: =SUMIF('TB 0225'!H:H,'MIS P&L'!B30,'TB 0225'!F:F)+'TB 0225'!P3 -> 4532.2401 | E31: =SUMIF('TB 0325'!H:H,'MIS P&L'!B30,'TB 0325'!F:F)+'TB 0325'!P8 -> 8965.1278 | F31: =SUMIF('TB 0425'!H:H,'MIS P&L'!B30,'TB 0425'!F:F)+'TB 0425'!R8 -> 12713.778 | G31: =SUMIF('TB 0525'!H:H,'MIS P&L'!B30,'TB 0525'!F:F)+'TB 0525'!R3 -> 15651.703 | H31: =SUMIF('TB 0625'!H:H,'MIS P&L'!B30,'TB 0625'!F:F)+'TB 0625'!M3+'TB 0625'!M8+'TB 0625'!M9 -> 19018.079 | I31: =SUMIF('TB 0725'!H:H,'MIS P&L'!B31,'TB 0725'!F:F)+'TB 0725'!L3+'TB 0725'!L8+'TB 0725'!L9 -> 21513.096 | J31: =SUMIF('TB 0825'!H:H,'MIS P&L'!B31,'TB 0825'!F:F)+'TB 0825'!L3+'TB 0825'!L8+'TB 0825'!L9 -> 24158.767 | K31: =SUMIF('TB 0925'!H:H,'MIS P&L'!B31,'TB 0925'!F:F)+'TB 0925'!M7+'TB 0925'!M8+'TB 0925'!M9 -> 26039.959 | L31: =SUMIF('TB 1025'!H:H,'MIS P&L'!B31,'TB 1025'!F:F)+'TB 1025'!M7+'TB 1025'!M8+'TB 1025'!M9 -> 35040.783 | M31: =SUMIF('TB 1125'!H:H,'MIS P&L'!B31,'TB 1125'!F:F)+'TB 1125'!M7+'TB 1125'!M8+'TB 1125'!M9 -> 39255.002 | N31: =SUMIF('TB 1225'!H:H,'MIS P&L'!B31,'TB 1225'!F:F)+'TB 1225'!M7+'TB 1225'!M8+'TB 1225'!M9 -> 45501.106
B32: Recruitment Cost | C32: 0 | D32: =SUMIF('TB 0225'!H:H,'MIS P&L'!B32,'TB 0225'!F:F) -> 2074 | E32: =SUMIF('TB 0325'!H:H,'MIS P&L'!B32,'TB 0325'!F:F) -> 176.933 | F32: =SUMIF('TB 0425'!H:H,'MIS P&L'!B32,'TB 0425'!F:F) -> 110 | G32: =SUMIF('TB 0525'!H:H,'MIS P&L'!B32,'TB 0525'!F:F) -> 705.326 | H32: =SUMIF('TB 0625'!H:H,'MIS P&L'!B32,'TB 0625'!F:F) -> 238.618 | I32: =SUMIF('TB 0725'!H:H,'MIS P&L'!B32,'TB 0725'!F:F) -> 1035.2 | J32: =SUMIF('TB 0825'!H:H,'MIS P&L'!B32,'TB 0825'!F:F) -> 342.175 | K32: =SUMIF('TB 0925'!H:H,'MIS P&L'!B32,'TB 0925'!F:F) -> 2 | L32: =SUMIF('TB 1025'!H:H,'MIS P&L'!B32,'TB 1025'!F:F) -> 147.942 | M32: =SUMIF('TB 1125'!H:H,'MIS P&L'!B32,'TB 1125'!F:F) -> 67.95 | N32: =SUMIF('TB 1225'!H:H,'MIS P&L'!B32,'TB 1225'!F:F) -> 266.912
B33: Tech Cost | C33: =SUMIF('TB 0125'!H:H,'MIS P&L'!B33,'TB 0125'!F:F) -> 373.25872 | D33: =SUMIF('TB 0225'!H:H,'MIS P&L'!B33,'TB 0225'!F:F) -> 518.67665 | E33: =SUMIF('TB 0325'!H:H,'MIS P&L'!B33,'TB 0325'!F:F) -> 549.93001 | F33: =SUMIF('TB 0425'!H:H,'MIS P&L'!B33,'TB 0425'!F:F) -> 1044.1697 | G33: =SUMIF('TB 0525'!H:H,'MIS P&L'!B33,'TB 0525'!F:F) -> 1383.7629 | H33: =SUMIF('TB 0625'!H:H,'MIS P&L'!B33,'TB 0625'!F:F) -> 1711.9282 | I33: =SUMIF('TB 0725'!H:H,'MIS P&L'!B33,'TB 0725'!F:F) -> 1849.1917 | J33: =SUMIF('TB 0825'!H:H,'MIS P&L'!B33,'TB 0825'!F:F) -> 2314.7726 | K33: =SUMIF('TB 0925'!H:H,'MIS P&L'!B33,'TB 0925'!F:F) -> 2765.2969 | L33: =SUMIF('TB 1025'!H:H,'MIS P&L'!B33,'TB 1025'!F:F) -> 3971.0149 | M33: =SUMIF('TB 1125'!H:H,'MIS P&L'!B33,'TB 1125'!F:F) -> 3401.2811 | N33: =SUMIF('TB 1225'!H:H,'MIS P&L'!B33,'TB 1225'!F:F) -> 2866.5096
B34: Other Costs | C34: =SUM(C35:C37) -> 487.48961 | D34: =SUM(D35:D37) -> 711.6444 | E34: =SUM(E35:E37) -> 860.95439 | F34: =SUM(F35:F37) -> 657.09742 | G34: =SUM(G35:G37) -> 1377.6578 | H34: =SUM(H35:H37) -> 1663.7004 | I34: =SUM(I35:I37) -> 2264.6548 | J34: =SUM(J35:J37) -> 2190.7756 | ... N34: =SUM(N35:N37) -> 5430.6649
B35: Professional Fees | C35: =SUMIF('TB 0125'!H:H,'MIS P&L'!B35,'TB 0125'!F:F) -> 109 | D35: =SUMIF('TB 0225'!H:H,'MIS P&L'!B35,'TB 0225'!F:F) -> 109 | E35: =SUMIF('TB 0325'!H:H,'MIS P&L'!B35,'TB 0325'!F:F) -> 237.58 | F35: =SUMIF('TB 0425'!H:H,'MIS P&L'!B35,'TB 0425'!F:F) -> 128.23 | G35: =SUMIF('TB 0525'!H:H,'MIS P&L'!B35,'TB 0525'!F:F) -> 440 | H35: =SUMIF('TB 0625'!H:H,'MIS P&L'!B35,'TB 0625'!F:F) -> 377.24 | I35: =SUMIF('TB 0725'!H:H,'MIS P&L'!B35,'TB 0725'!F:F) -> 750.95 | J35: =SUMIF('TB 0825'!H:H,'MIS P&L'!B35,'TB 0825'!F:F) -> 772.735 | K35: =SUMIF('TB 0925'!H:H,'MIS P&L'!B35,'TB 0925'!F:F) -> 794.13966 | L35: =SUMIF('TB 1025'!H:H,'MIS P&L'!B35,'TB 1025'!F:F) -> 1258.35 | M35: =SUMIF('TB 1125'!H:H,'MIS P&L'!B35,'TB 1125'!F:F) -> 2211.437 | N35: =SUMIF('TB 1225'!H:H,'MIS P&L'!B35,'TB 1225'!F:F) -> 3080.8271
B36: Office and Admin Expenses | C36: =SUMIF('TB 0125'!H:H,'MIS P&L'!B36,'TB 0125'!F:F) -> 295.994 | D36: =SUMIF('TB 0225'!H:H,'MIS P&L'!B36,'TB 0225'!F:F) -> 301.251 | E36: =SUMIF('TB 0325'!H:H,'MIS P&L'!B36,'TB 0325'!F:F) -> 586.42496 | F36: =SUMIF('TB 0425'!H:H,'MIS P&L'!B36,'TB 0425'!F:F) -> 466.89788 | G36: =SUMIF('TB 0525'!H:H,'MIS P&L'!B36,'TB 0525'!F:F) -> 814.74806 | H36: =SUMIF('TB 0625'!H:H,'MIS P&L'!B36,'TB 0625'!F:F) -> 1175.4557 | I36: =SUMIF('TB 0725'!H:H,'MIS P&L'!B36,'TB 0725'!F:F) -> 1349.8984 | J36: =SUMIF('TB 0825'!H:H,'MIS P&L'!B36,'TB 0825'!F:F) -> 1283.3703 | K36: =SUMIF('TB 0925'!H:H,'MIS P&L'!B36,'TB 0925'!F:F) -> 829.02504 | L36: =SUMIF('TB 1025'!H:H,'MIS P&L'!B36,'TB 1025'!F:F) -> 1607.0294 | M36: =SUMIF('TB 1125'!H:H,'MIS P&L'!B36,'TB 1125'!F:F) -> 2756.9744 | N36: =SUMIF('TB 1225'!H:H,'MIS P&L'!B36,'TB 1225'!F:F) -> 2293.5917
B37: Miscellaneous Expenses | C37: =SUMIF('TB 0125'!H:H,'MIS P&L'!B37,'TB 0125'!F:F) -> 82.49561 | D37: =SUMIF('TB 0225'!H:H,'MIS P&L'!B37,'TB 0225'!F:F) -> 301.3934 | E37: =SUMIF('TB 0325'!H:H,'MIS P&L'!B37,'TB 0325'!F:F) -> 36.94943 | F37: =SUMIF('TB 0425'!H:H,'MIS P&L'!B37,'TB 0425'!F:F) -> 61.96954 | G37: =SUMIF('TB 0525'!H:H,'MIS P&L'!B37,'TB 0525'!F:F) -> 122.90971 | H37: =SUMIF('TB 0625'!H:H,'MIS P&L'!B37,'TB 0625'!F:F) -> 111.00471 | I37: =SUMIF('TB 0725'!H:H,'MIS P&L'!B37,'TB 0725'!F:F) -> 163.80649 | J37: =SUMIF('TB 0825'!H:H,'MIS P&L'!B37,'TB 0825'!F:F) -> 134.67031 | K37: =SUMIF('TB 0925'!H:H,'MIS P&L'!B37,'TB 0925'!F:F) -> 282.65369 | L37: =SUMIF('TB 1025'!H:H,'MIS P&L'!B37,'TB 1025'!F:F) -> 82.52246 | M37: =SUMIF('TB 1125'!H:H,'MIS P&L'!B37,'TB 1125'!F:F) -> 43.1627 | N37: =SUMIF('TB 1225'!H:H,'MIS P&L'!B37,'TB 1225'!F:F) -> 56.24615
B39: Adjusted EBITDA | C39: =C23-C26-C30-C33-C34 -> -5271.4059 | D39: =D23-D26-D30-D33-D34 -> -10756.615 | E39: =E23-E26-E30-E33-E34 -> -14251.324 | F39: =F23-F26-F30-F33-F34 -> -22638.783 | G39: =G23-G26-G30-G33-G34 -> -34835.869 | H39: =H23-H26-H30-H33-H34 -> -50197.023 | I39: =I23-I26-I30-I33-I34 -> -63747.299 | J39: =J23-J26-J30-J33-J34 -> -91234.89 | ... N39: =N23-N26-N30-N33-N34 -> -222893.09
B40: EBITDA % | C40: =C39/C7 -> -3.1276552 | D40: =D39/D7 -> -6.1371706 | E40: =E39/E7 -> -5.8050371 | F40: =F39/F7 -> -6.6983571 | G40: =G39/G7 -> -4.6048159 | H40: =H39/H7 -> -4.8603162 | I40: =I39/I7 -> -4.2696276 | J40: =J39/J7 -> -3.3109172 | ... N40: =N39/N7 -> -1.9088316
B42: Fund Raising Expenses | C42: =SUMIF('TB 0125'!H:H,'MIS P&L'!B42,'TB 0125'!F:F) -> 1200.5 | D42: =SUMIF('TB 0225'!H:H,'MIS P&L'!B42,'TB 0225'!F:F) -> 502.26 | E42: =SUMIF('TB 0325'!H:H,'MIS P&L'!B42,'TB 0325'!F:F) -> 1515 | F42: =SUMIF('TB 0425'!H:H,'MIS P&L'!B42,'TB 0425'!F:F) -> 601 | G42: =SUMIF('TB 0525'!H:H,'MIS P&L'!B42,'TB 0525'!F:F) -> 148.5 | H42: =SUMIF('TB 0625'!H:H,'MIS P&L'!B42,'TB 0625'!F:F) -> 3184.84 | I42: =SUMIF('TB 0725'!H:H,'MIS P&L'!B42,'TB 0725'!F:F) -> 430.15 | J42: =SUMIF('TB 0825'!H:H,'MIS P&L'!B42,'TB 0825'!F:F) -> 0 | K42: =SUMIF('TB 0925'!H:H,'MIS P&L'!B42,'TB 0925'!F:F) -> 0 | L42: =SUMIF('TB 1025'!H:H,'MIS P&L'!B42,'TB 1025'!F:F) -> 0 | M42: =SUMIF('TB 1125'!H:H,'MIS P&L'!B42,'TB 1125'!F:F) -> 0 | N42: =SUMIF('TB 1225'!H:H,'MIS P&L'!B42,'TB 1225'!F:F) -> 0
B44: EBITDA | C44: =C39-C42 -> -6471.9059 | D44: =D39-D42 -> -11258.875 | E44: =E39-E42 -> -15766.324 | F44: =F39-F42 -> -23239.783 | G44: =G39-G42 -> -34984.369 | H44: =H39-H42 -> -53381.863 | I44: =I39-I42 -> -64177.449 | J44: =J39-J42 -> -91234.89 | ... N44: =N39-N42 -> -222893.09
B45: EBITDA % | C45: =C44/C7 -> -3.8399415 | D45: =D44/D7 -> -6.4237342 | E45: =E44/E7 -> -6.4221468 | F45: =F44/F7 -> -6.8761808 | G45: =G44/G7 -> -4.6244455 | H45: =H44/H7 -> -5.1686877 | I45: =I44/I7 -> -4.2984379 | J45: =J44/J7 -> -3.3109172 | ... N45: =N44/N7 -> -1.9088316
B47: Depreciation | C47: =SUMIF('TB 0125'!H:H,'MIS P&L'!B47,'TB 0125'!F:F) -> 68.039 | D47: =SUMIF('TB 0225'!H:H,'MIS P&L'!B47,'TB 0225'!F:F) -> 77.932 | E47: =SUMIF('TB 0325'!H:H,'MIS P&L'!B47,'TB 0325'!F:F) -> 160.17333 | F47: =SUMIF('TB 0425'!H:H,'MIS P&L'!B47,'TB 0425'!F:F) -> 213.09815 | G47: =SUMIF('TB 0525'!H:H,'MIS P&L'!B47,'TB 0525'!F:F) -> 266.90296 | H47: =SUMIF('TB 0625'!H:H,'MIS P&L'!B47,'TB 0625'!F:F) -> 293.91167 | I47: =SUMIF('TB 0725'!H:H,'MIS P&L'!B47,'TB 0725'!F:F) -> 338.10246 | J47: =SUMIF('TB 0825'!H:H,'MIS P&L'!B47,'TB 0825'!F:F) -> 395.112 | K47: =SUMIF('TB 0925'!H:H,'MIS P&L'!B47,'TB 0925'!F:F) -> 653.15802 | L47: =SUMIF('TB 1025'!H:H,'MIS P&L'!B47,'TB 1025'!F:F) -> 856.74808 | M47: =SUMIF('TB 1125'!H:H,'MIS P&L'!B47,'TB 1125'!F:F) -> 1006.8347 | N47: =SUMIF('TB 1225'!H:H,'MIS P&L'!B47,'TB 1225'!F:F) -> 1184.2885
B48: Interest Income | C48: =-SUMIF('TB 0125'!H:H,'MIS P&L'!B48,'TB 0125'!F:F) -> 530.43759 | D48: =-SUMIF('TB 0225'!H:H,'MIS P&L'!B48,'TB 0225'!F:F) -> 2475.789 | E48: =-SUMIF('TB 0325'!H:H,'MIS P&L'!B48,'TB 0325'!F:F) -> 3149.74 | F48: =-SUMIF('TB 0425'!H:H,'MIS P&L'!B48,'TB 0425'!F:F) -> 2627.8147 | G48: =-SUMIF('TB 0525'!H:H,'MIS P&L'!B48,'TB 0525'!F:F) -> 2553.0613 | H48: =-SUMIF('TB 0625'!H:H,'MIS P&L'!B48,'TB 0625'!F:F) -> 9875.7241 | I48: =-SUMIF('TB 0725'!H:H,'MIS P&L'!B48,'TB 0725'!F:F) -> 10016.751 | J48: =-SUMIF('TB 0825'!H:H,'MIS P&L'!B48,'TB 0825'!F:F) -> 9834.8399 | K48: =-SUMIF('TB 0925'!H:H,'MIS P&L'!B48,'TB 0925'!F:F) -> 10218.875 | L48: =-SUMIF('TB 1025'!H:H,'MIS P&L'!B48,'TB 1025'!F:F) -> 10608.585 | M48: =-SUMIF('TB 1125'!H:H,'MIS P&L'!B48,'TB 1125'!F:F) -> 17681.218 | N48: =-SUMIF('TB 1225'!H:H,'MIS P&L'!B48,'TB 1225'!F:F) -> 18913.496
B50: PBT | C50: =C44-C47+C48 -> -6009.5073 | D50: =D44-D47+D48 -> -8861.0183 | E50: =E44-E47+E48 -> -12776.758 | F50: =F44-F47+F48 -> -20825.066 | G50: =G44-G47+G48 -> -32698.211 | H50: =H44-H47+H48 -> -43800.051 | I50: =I44-I47+I48 -> -54498.801 | J50: =J44-J47+J48 -> -81795.162 | ... N50: =N44-N47+N48 -> -205163.89
B51: PBT % | C51: =C50/C7 -> -3.565589 | D51: =D50/D7 -> -5.0556406 | E51: =E50/E7 -> -5.2043972 | F51: =F50/F7 -> -6.1617151 | G51: =G50/G7 -> -4.3222472 | H51: =H50/H7 -> -4.2409307 | I51: =I50/I7 -> -3.6501873 | J51: =J50/J7 -> -2.9683492 | ... N51: =N50/N7 -> -1.7570006
B53: Tax | C53: 0 | D53: 0 | E53: 0 | F53: 0 | G53: 0 | H53: 0 | I53: 0 | J53: 0 | K53: =-SUMIF('TB 0925'!H:H,'MIS P&L'!B53,'TB 0925'!F:F) -> 0 | L53: 0 | M53: 0 | N53: 0
...

Sheet Unit Economics
B2: Jobs per Day | C2: ='Key Metrics'!C20 -> 228.76667 | D2: ='Key Metrics'!D20 -> 250.63333 | E2: ='Key Metrics'!E20 -> 354.73333 | F2: ='Key Metrics'!F20 -> 499.33333 | G2: ='Key Metrics'!G20 -> 1135.129 | H2: ='Key Metrics'!H20 -> 1573.7 | I2: ='Key Metrics'!I20 -> 2199.871 | J2: ='Key Metrics'!J20 -> 3832.5161 | ... L2: ='Key Metrics'!L20 -> 9957.0323 | M2: ='Key Metrics'!#REF! -> #REF! | N2: ='Key Metrics'!M20 -> 12521.167 | O2: ='Key Metrics'!#REF! -> #REF! | P2: ='Key Metrics'!#REF! -> #REF! | Q2: ='Key Metrics'!#REF! -> #REF! | R2: ='Key Metrics'!#REF! -> #REF!
B3: Hrs per Day | C3: ='Key Metrics'!C26 -> 294.99194 | D3: ='Key Metrics'!D26 -> 342.96429 | E3: ='Key Metrics'!E26 -> 434.10484 | F3: ='Key Metrics'!F26 -> 615.43333 | G3: ='Key Metrics'!G26 -> 1337.9194 | H3: ='Key Metrics'!H26 -> 1829.1667 | I3: ='Key Metrics'!I26 -> 2557.0806 | J3: ='Key Metrics'!J26 -> 4678.5161 | ... L3: ='Key Metrics'!L26 -> 13086.798 | M3: ='Key Metrics'!#REF! -> #REF! | N3: ='Key Metrics'!M26 -> 15568.681 | O3: ='Key Metrics'!#REF! -> #REF! | P3: ='Key Metrics'!#REF! -> #REF! | Q3: ='Key Metrics'!#REF! -> #REF! | R3: ='Key Metrics'!#REF! -> #REF!
B5: Unit Economics | C5: Actual | D5: Actual | E5: Actual | F5: Actual | G5: Actual | H5: Actual | I5: Actual | J5: Actual | K5: Actual | L5: Actual | M5: Plan | N5: Actual | O5: Forecast | P5: Plan | Q5: Rev Forecast | R5: Plan
B6: All Values (in INR per Job) | C6: 45658 | D6: 45689 | E6: 45717 | F6: ='MIS P&L'!F6 -> 45748 | G6: ='MIS P&L'!G6 -> 45778 | H6: ='MIS P&L'!H6 -> 45809 | I6: ='MIS P&L'!I6 -> 45839 | J6: ='MIS P&L'!J6 -> 45870 | K6: ='MIS P&L'!K6 -> 45901 | L6: ='MIS P&L'!L6 -> 45931 | M6: =K6+31 -> 45932 | N6: ='MIS P&L'!M6 -> 45962 | O6: 45963 | P6: =M6+31 -> 45963 | Q6: 46022 | R6: =P6+31 -> 45994
B7: Revenue | C7: =('MIS P&L'!C7)*10^3/'MIS P&L'!C$2 -> 245.58033 | D7: =('MIS P&L'!D7)*10^3/'MIS P&L'!D$2 -> 233.10273 | E7: =('MIS P&L'!E7)*10^3/'MIS P&L'!E$2 -> 230.68904 | F7: =('MIS P&L'!F7)*10^3/'MIS P&L'!F$2 -> 225.6176 | G7: =('MIS P&L'!G7)*10^3/'MIS P&L'!G$2 -> 214.98465 | H7: =('MIS P&L'!H7)*10^3/'MIS P&L'!H$2 -> 218.76117 | I7: =('MIS P&L'!I7)*10^3/'MIS P&L'!I$2 -> 218.93384 | J7: =('MIS P&L'!J7)*10^3/'MIS P&L'!J$2 -> 231.93535 | ... L7: =('MIS P&L'!L7)*10^3/'MIS P&L'!L$2 -> 240.55474 | M7: =('MIS P&L'!#REF!)*10^3/'MIS P&L'!#REF! -> #REF! | N7: =('MIS P&L'!M7)*10^3/'MIS P&L'!M$2 -> 225.28644 | O7: =('MIS P&L'!#REF!)*10^3/'MIS P&L'!#REF! -> #REF! | P7: =('MIS P&L'!#REF!)*10^3/'MIS P&L'!#REF! -> #REF! | Q7: =('MIS P&L'!#REF!)*10^3/'MIS P&L'!#REF! -> #REF! | R7: =('MIS P&L'!#REF!)*10^3/'MIS P&L'!#REF! -> #REF!
B8: Service Cost | C8: =('MIS P&L'!C8)*10^3/'MIS P&L'!C$2 -> 191.8646 | D8: =('MIS P&L'!D8)*10^3/'MIS P&L'!D$2 -> 240.53149 | E8: =('MIS P&L'!E8)*10^3/'MIS P&L'!E$2 -> 223.42346 | F8: =('MIS P&L'!F8)*10^3/'MIS P&L'!F$2 -> 311.50788 | G8: =('MIS P&L'!G8)*10^3/'MIS P&L'!G$2 -> 287.74425 | H8: =('MIS P&L'!H8)*10^3/'MIS P&L'!H$2 -> 343.01441 | I8: =('MIS P&L'!I8)*10^3/'MIS P&L'!I$2 -> 304.96776 | J8: =('MIS P&L'!J8)*10^3/'MIS P&L'!J$2 -> 293.73579 | ... L8: =('MIS P&L'!L8)*10^3/'MIS P&L'!L$2 -> 260.62501 | M8: =('MIS P&L'!#REF!)*10^3/'MIS P&L'!#REF! -> #REF! | N8: =('MIS P&L'!M8)*10^3/'MIS P&L'!M$2 -> 248.55132 | O8: =('MIS P&L'!#REF!)*10^3/'MIS P&L'!#REF! -> #REF! | P8: =('MIS P&L'!#REF!)*10^3/'MIS P&L'!#REF! -> #REF! | Q8: =('MIS P&L'!#REF!)*10^3/'MIS P&L'!#REF! -> #REF! | R8: =('MIS P&L'!#REF!)*10^3/'MIS P&L'!#REF! -> #REF!
B10: GST | C10: =('MIS P&L'!C10)*10^3/'MIS P&L'!C$2 -> 16.240445 | D10: =('MIS P&L'!D10)*10^3/'MIS P&L'!D$2 -> 14.242423 | E10: =('MIS P&L'!E10)*10^3/'MIS P&L'!E$2 -> 13.692852 | F10: =('MIS P&L'!F10)*10^3/'MIS P&L'!F$2 -> 14.620283 | G10: =('MIS P&L'!G10)*10^3/'MIS P&L'!G$2 -> 14.13595 | H10: =('MIS P&L'!H10)*10^3/'MIS P&L'!H$2 -> 14.292926 | I10: =('MIS P&L'!I10)*10^3/'MIS P&L'!I$2 -> 14.563896 | J10: =('MIS P&L'!J10)*10^3/'MIS P&L'!J$2 -> 15.375671 | ... L10: =('MIS P&L'!L10)*10^3/'MIS P&L'!L$2 -> 10.031803 | M10: =('MIS P&L'!#REF!)*10^3/'MIS P&L'!#REF! -> #REF! | N10: =('MIS P&L'!M10)*10^3/'MIS P&L'!M$2 -> 9.6921039 | O10: =('MIS P&L'!#REF!)*10^3/'MIS P&L'!#REF! -> #REF! | P10: =('MIS P&L'!#REF!)*10^3/'MIS P&L'!#REF! -> #REF! | Q10: =('MIS P&L'!#REF!)*10^3/'MIS P&L'!#REF! -> #REF! | R10: =('MIS P&L'!#REF!)*10^3/'MIS P&L'!#REF! -> #REF!
B11: Promotions & Discounts | C11: =('MIS P&L'!C11)*10^3/'MIS P&L'!C$2 -> 6.9492933 | D11: =('MIS P&L'!D11)*10^3/'MIS P&L'!D$2 -> 9.0867137 | E11: =('MIS P&L'!E11)*10^3/'MIS P&L'!E$2 -> 2.0612667 | F11: =('MIS P&L'!F11)*10^3/'MIS P&L'!F$2 -> 2.2369826 | G11: =('MIS P&L'!G11)*10^3/'MIS P&L'!G$2 -> 0.55983404 | H11: =('MIS P&L'!H11)*10^3/'MIS P&L'!H$2 -> 0.92832179 | I11: =('MIS P&L'!I11)*10^3/'MIS P&L'!I$2 -> 5.1001972 | J11: =('MIS P&L'!J11)*10^3/'MIS P&L'!J$2 -> 9.8435122 | ... L11: =('MIS P&L'!L11)*10^3/'MIS P&L'!L$2 -> 27.962588 | M11: =('MIS P&L'!#REF!)*10^3/'MIS P&L'!#REF! -> #REF! | N11: =('MIS P&L'!M11)*10^3/'MIS P&L'!M$2 -> 33.998544 | O11: =('MIS P&L'!#REF!)*10^3/'MIS P&L'!#REF! -> #REF! | P11: =('MIS P&L'!#REF!)*10^3/'MIS P&L'!#REF! -> #REF! | Q11: =('MIS P&L'!#REF!)*10^3/'MIS P&L'!#REF! -> #REF! | R11: =('MIS P&L'!#REF!)*10^3/'MIS P&L'!#REF! -> #REF!
B12: Payment Gateway Cost | C12: =('MIS P&L'!C12)*10^3/'MIS P&L'!C$2 -> 2.6651144 | D12: =('MIS P&L'!D12)*10^3/'MIS P&L'!D$2 -> 2.2726214 | E12: =('MIS P&L'!E12)*10^3/'MIS P&L'!E$2 -> 2.0121227 | F12: =('MIS P&L'!F12)*10^3/'MIS P&L'!F$2 -> 2.1654272 | G12: =('MIS P&L'!G12)*10^3/'MIS P&L'!G$2 -> 0.65759271 | H12: =('MIS P&L'!H12)*10^3/'MIS P&L'!H$2 -> 0.7151541 | I12: =('MIS P&L'!I12)*10^3/'MIS P&L'!I$2 -> 0.68225556 | J12: =('MIS P&L'!J12)*10^3/'MIS P&L'!J$2 -> 0.41847712 | ... L12: =('MIS P&L'!L12)*10^3/'MIS P&L'!L$2 -> 0.30018049 | M12: =('MIS P&L'!#REF!)*10^3/'MIS P&L'!#REF! -> #REF! | N12: =('MIS P&L'!M12)*10^3/'MIS P&L'!M$2 -> 0.30711326 | O12: =('MIS P&L'!#REF!)*10^3/'MIS P&L'!#REF! -> #REF! | P12: =('MIS P&L'!#REF!)*10^3/'MIS P&L'!#REF! -> #REF! | Q12: =('MIS P&L'!#REF!)*10^3/'MIS P&L'!#REF! -> #REF! | R12: =('MIS P&L'!#REF!)*10^3/'MIS P&L'!#REF! -> #REF!
B14: Gross Profit | C14: =C7-C8-C10-C11-C12 -> 27.860882 | D14: =D7-D8-D10-D11-D12 -> -33.030516 | E14: =E7-E8-E10-E11-E12 -> -10.500657 | F14: =F7-F8-F10-F11-F12 -> -104.91298 | G14: =G7-G8-G10-G11-G12 -> -88.112971 | H14: =H7-H8-H10-H11-H12 -> -140.18964 | I14: =I7-I8-I10-I11-I12 -> -106.38027 | J14: =J7-J8-J10-J11-J12 -> -87.438103 | ... R14: =R7-R8-R10-R11-R12 -> #REF!
B15: Gross Profit % | C15: =C14/C7 -> 0.11344916 | D15: =D14/D7 -> -0.1416994 | E15: =E14/E7 -> -0.045518663 | F15: =F14/F7 -> -0.46500352 | G15: =G14/G7 -> -0.40985703 | H15: =H14/H7 -> -0.64083419 | I15: =I14/I7 -> -0.48590146 | J15: =J14/J7 -> -0.37699343 | ... R15: =R14/R7 -> #REF!
B17: Training Centre Expenses | C17: =('MIS P&L'!C17)*10^3/'MIS P&L'!C$2 -> 22.501539 | D17: =('MIS P&L'!D17)*10^3/'MIS P&L'!D$2 -> 73.900696 | E17: =('MIS P&L'!E17)*10^3/'MIS P&L'!E$2 -> 35.575638 | F17: =('MIS P&L'!F17)*10^3/'MIS P&L'!F$2 -> 71.537003 | G17: =('MIS P&L'!G17)*10^3/'MIS P&L'!G$2 -> 60.290025 | H17: =('MIS P&L'!H17)*10^3/'MIS P&L'!H$2 -> 38.955568 | I17: =('MIS P&L'!I17)*10^3/'MIS P&L'!I$2 -> 31.236091 | J17: =('MIS P&L'!J17)*10^3/'MIS P&L'!J$2 -> 20.164081 | ... L17: =('MIS P&L'!L17)*10^3/'MIS P&L'!L$2 -> 14.610512 | M17: =('MIS P&L'!#REF!)*10^3/'MIS P&L'!#REF! -> #REF! | N17: =('MIS P&L'!M17)*10^3/'MIS P&L'!M$2 -> 12.404039 | O17: =('MIS P&L'!#REF!)*10^3/'MIS P&L'!#REF! -> #REF! | P17: =('MIS P&L'!#REF!)*10^3/'MIS P&L'!#REF! -> #REF! | Q17: =('MIS P&L'!#REF!)*10^3/'MIS P&L'!#REF! -> #REF! | R17: =('MIS P&L'!#REF!)*10^3/'MIS P&L'!#REF! -> #REF!
B18: Managerial Cost | C18: =('MIS P&L'!C18)*10^3/'MIS P&L'!C$2 -> 19.750546 | D18: =('MIS P&L'!D18)*10^3/'MIS P&L'!D$2 -> 33.206676 | E18: =('MIS P&L'!E18)*10^3/'MIS P&L'!E$2 -> 41.061549 | F18: =('MIS P&L'!F18)*10^3/'MIS P&L'!F$2 -> 61.011081 | G18: =('MIS P&L'!G18)*10^3/'MIS P&L'!G$2 -> 39.008326 | H18: =('MIS P&L'!H18)*10^3/'MIS P&L'!H$2 -> 41.823967 | I18: =('MIS P&L'!I18)*10^3/'MIS P&L'!I$2 -> 42.112957 | J18: =('MIS P&L'!J18)*10^3/'MIS P&L'!J$2 -> 36.686576 | ... L18: =('MIS P&L'!L18)*10^3/'MIS P&L'!L$2 -> 19.081594 | M18: =('MIS P&L'!#REF!)*10^3/'MIS P&L'!#REF! -> #REF! | N18: =('MIS P&L'!M18)*10^3/'MIS P&L'!M$2 -> 15.521143 | O18: =('MIS P&L'!#REF!)*10^3/'MIS P&L'!#REF! -> #REF! | P18: =('MIS P&L'!#REF!)*10^3/'MIS P&L'!#REF! -> #REF! | Q18: =('MIS P&L'!#REF!)*10^3/'MIS P&L'!#REF! -> #REF! | R18: =('MIS P&L'!#REF!)*10^3/'MIS P&L'!#REF! -> #REF!
B19: Sourcing & Onboarding Cost | C19: =('MIS P&L'!C19)*10^3/'MIS P&L'!C$2 -> 38.649194 | D19: =('MIS P&L'!D19)*10^3/'MIS P&L'!D$2 -> 65.09607 | E19: =('MIS P&L'!E19)*10^3/'MIS P&L'!E$2 -> 91.0168 | F19: =('MIS P&L'!F19)*10^3/'MIS P&L'!F$2 -> 98.093909 | G19: =('MIS P&L'!G19)*10^3/'MIS P&L'!G$2 -> 51.735599 | H19: =('MIS P&L'!H19)*10^3/'MIS P&L'!H$2 -> 98.843823 | I19: =('MIS P&L'!I19)*10^3/'MIS P&L'!I$2 -> 69.13969 | J19: =('MIS P&L'!J19)*10^3/'MIS P&L'!J$2 -> 56.979489 | ... L19: =('MIS P&L'!L19)*10^3/'MIS P&L'!L$2 -> 43.843598 | M19: =('MIS P&L'!#REF!)*10^3/'MIS P&L'!#REF! -> #REF! | N19: =('MIS P&L'!M19)*10^3/'MIS P&L'!M$2 -> 35.61351 | O19: =('MIS P&L'!#REF!)*10^3/'MIS P&L'!#REF! -> #REF! | P19: =('MIS P&L'!#REF!)*10^3/'MIS P&L'!#REF! -> #REF! | Q19: =('MIS P&L'!#REF!)*10^3/'MIS P&L'!#REF! -> #REF! | R19: =('MIS P&L'!#REF!)*10^3/'MIS P&L'!#REF! -> #REF!
B20: Customer Success Cost | C20: =('MIS P&L'!C20)*10^3/'MIS P&L'!C$2 -> 11.308757 | D20: =('MIS P&L'!D20)*10^3/'MIS P&L'!D$2 -> 7.1818061 | E20: =('MIS P&L'!E20)*10^3/'MIS P&L'!E$2 -> 20.14875 | F20: =('MIS P&L'!F20)*10^3/'MIS P&L'!F$2 -> 23.453138 | G20: =('MIS P&L'!G20)*10^3/'MIS P&L'!G$2 -> 17.680582 | H20: =('MIS P&L'!H20)*10^3/'MIS P&L'!H$2 -> 14.596733 | I20: =('MIS P&L'!I20)*10^3/'MIS P&L'!I$2 -> 9.575353 | J20: =('MIS P&L'!J20)*10^3/'MIS P&L'!J$2 -> 6.5010483 | ... L20: =('MIS P&L'!L20)*10^3/'MIS P&L'!L$2 -> 5.394008 | M20: =('MIS P&L'!#REF!)*10^3/'MIS P&L'!#REF! -> #REF! | N20: =('MIS P&L'!M20)*10^3/'MIS P&L'!M$2 -> 6.1390745 | O20: =('MIS P&L'!#REF!)*10^3/'MIS P&L'!#REF! -> #REF! | P20: =('MIS P&L'!#REF!)*10^3/'MIS P&L'!#REF! -> #REF! | Q20: =('MIS P&L'!#REF!)*10^3/'MIS P&L'!#REF! -> #REF! | R20: =('MIS P&L'!#REF!)*10^3/'MIS P&L'!#REF! -> #REF!
B21: Other Operational Cost | C21: =('MIS P&L'!C21)*10^3/'MIS P&L'!C$2 -> 0 | D21: =('MIS P&L'!D21)*10^3/'MIS P&L'!D$2 -> 0 | E21: =('MIS P&L'!E21)*10^3/'MIS P&L'!E$2 -> 0 | F21: =('MIS P&L'!F21)*10^3/'MIS P&L'!F$2 -> 6.6301575 | G21: =('MIS P&L'!G21)*10^3/'MIS P&L'!G$2 -> 13.319309 | H21: =('MIS P&L'!H21)*10^3/'MIS P&L'!H$2 -> 27.488373 | I21: =('MIS P&L'!I21)*10^3/'MIS P&L'!I$2 -> 35.712172 | J21: =('MIS P&L'!J21)*10^3/'MIS P&L'!J$2 -> 16.230288 | ... L21: =('MIS P&L'!L21)*10^3/'MIS P&L'!L$2 -> 3.3600418 | M21: =('MIS P&L'!#REF!)*10^3/'MIS P&L'!#REF! -> #REF! | N21: =('MIS P&L'!M21)*10^3/'MIS P&L'!M$2 -> 2.7850686 | O21: =('MIS P&L'!#REF!)*10^3/'MIS P&L'!#REF! -> #REF! | P21: =('MIS P&L'!#REF!)*10^3/'MIS P&L'!#REF! -> #REF! | Q21: =('MIS P&L'!#REF!)*10^3/'MIS P&L'!#REF! -> #REF! | R21: =('MIS P&L'!#REF!)*10^3/'MIS P&L'!#REF! -> #REF!
B23: Operating Profit | C23: =C14-SUM(C17:C20) -> -64.349155 | D23: =D14-SUM(D17:D20) -> -212.41576 | E23: =E14-SUM(E17:E20) -> -198.30339 | F23: =F14-SUM(F17:F21) -> -365.63827 | G23: =G14-SUM(G17:G21) -> -270.14681 | H23: =H14-SUM(H17:H21) -> -361.8981 | I23: =I14-SUM(I17:I21) -> -294.15653 | J23: =J14-SUM(J17:J21) -> -223.99959 | K23: =K14-SUM(K17:K21) -> -170.01705 | L23: =L14-SUM(L17:L21) -> -144.65459 | M23: =M14-SUM(M17:M21) -> #REF! | ... R23: =R14-SUM(R17:R21) -> #REF!
B24: Operating Profit % | C24: =C23/C7 -> -0.26202894 | D24: =D23/D7 -> -0.91125387 | E24: =E23/E7 -> -0.8596134 | F24: =F23/F7 -> -1.6206106 | G24: =G23/G7 -> -1.2565865 | H24: =H23/H7 -> -1.6543068 | I24: =I23/I7 -> -1.3435864 | J24: =J23/J7 -> -0.96578458 | ... R24: =R23/R7 -> #REF!
